Workbook

Sheet 模型说明
A1: 中银E贷 + 港币基金三阶段策略模型（v6）
A3: 本次更新 | B3: “每月决策汇总”新增每月收到分红金额；新增“实际执行追踪”及“实际贷款明细”，用于逐月记录真实贷款、汇率、基金价格、每股分红和费用。
A5: 试算模块 | B5: 参数设置、每月决策汇总、月度资金流、贷款明细继续用于情景试算。默认每手500股、每股10港币、每股每月分红0.05港币。
A6: 实际模块 | B6: 实际执行追踪中黄色蓝字为每月实际输入。用户输入当月策略、贷款额、汇率、价格、手数、分红及费用后，持仓、现金池、还款来源、外部资金池和净资产自动滚动计算。
A7: 实际贷款 | B7: 实际贷款明细按每个月实际输入的贷款人民币额度建立独立12个月还息、到期还本计划，计息口径仍为Actual/360。
A8: 未来月份 | B8: 尚未发生的月份可将实际贷款额、分红和基金交易相关输入保持为0；已发生后再覆盖成真实数据。
A10: 资金优先级 | B10: 策略二新贷款抵还旧本金 → 内部现金池 → 策略三按整手卖基金 → 外部资金池。买基金找零、每月收到分红、卖出超额现金均进入内部现金池。
A12: 风险提示 | B12: 本模型用于记录和情景分析，不构成投资或借贷建议。实际贷款合同、基金价格、分红、费用与赎回到账时间应以真实记录为准。

Sheet 参数设置
A1: 参数设置（试算默认值）
A3: 基础及贷款
A4: 模型开始日 | B4: 46244 | C4: 首月
A5: 每月人民币标准金额 | B5: 23400 | C5: 试算值
A6: 连续贷款月数上限 | B6: 24 | C6: 默认24个月
A7: 汇率（人民币/港币） | B7: 0.86 | C7: 1港币兑换人民币
A8: 主策略期（月） | B8: 36 | C8: 三阶段
A9: 延伸追踪期（月） | B9: 12 | C9: 期后追踪
A11: 贷款年利率 | B11: 0.033 | C11: Actual/360
A12: 计息年基数 | B12: 360 | C12: Actual/360
A13: 贷款期限（月） | B13: 12 | C13: 每笔
A14: 每月结息日 | B14: 5 | C14: 首期按放款后第二个月
A15: 金额取整位数 | B15: 2 | C15: 人民币分
A17: 基金默认值
A18: 基金单位价格（港币/股） | B18: 10 | C18: 试算默认
A19: 每手股数 | B19: 500 | C19: 整手买卖
A20: 每股每月分红（港币） | B20: 0.05 | C20: 默认0.05
A21: 隐含年化现金分红率 | B21: =B20*12/B18 -> 0.06 | C21: 自动计算
A22: 申购费用率 | B22: 0 | C22: 试算默认
A23: 赎回费用率 | B23: 0 | C23: 试算默认

Sheet 每月决策汇总
A1: 每月决策汇总：整手买卖、分红、还款与资金分配
A6: 月份 | B6: 当月策略 | C6: 当月操作提示 | D6: 买入股数 | E6: 买入基金（港币） | F6: 找零入内部池 | G6: 当月收到分红 | H6: 卖出股数 | I6: 卖出基金净额 | J6: 应还本金（人民币） | K6: 应还利息（人民币） | L6: 总还款（港币） | M6: 新贷款抵还 | N6: 内部池用于还款 | O6: 外部资金池投入 | P6: 内部现金池期末 | Q6: 基金持仓股数 | R6: 基金市值 | S6: 未偿贷款（人民币） | T6: 策略净资产
A7: =月度资金流!A7 -> 46235 | B7: =月度资金流!B7 -> 策略一：消费贷款+买基金 | C7: =IF(D7>0,"买入 "&ROUND(D7,0)&" 股，支付 HK$"&ROUND(E7,0)&"，找零 HK$"&ROUND(F7,0)&"；分红 HK$"&ROUND(G7,0),IF(H7>0,"卖出 "&ROUND(H7,0)&" 股，净收 HK$"&ROUND(I7,0)&"；内部池支付 HK$"&ROUND(N7,0)&"；分红 HK$"&ROUND(G7,0),IF(M7>0,"新贷款抵还 HK$"&ROUND(M7,0)&"；内部池支付 HK$"&ROUND(N7,0)&"；分红 HK$"&ROUND(G7,0),IF(L7>0,"应还 HK$"&ROUND(L7,0)&"；内部池支付 HK$"&ROUND(N7,0)&IF(O7>0,"；外部池投入 HK$"&ROUND(O7,0),"")&"；分红 HK$"&ROUND(G7,0),IF(G7>0,"收到分红 HK$"&ROUND(G7,0),"无需操作"))))) -> 买入 2500 股，支付 HK$25000，找零 HK$2209；分红 HK$0 | D7: =月度资金流!H7 -> 2500 | E7: =月度资金流!I7 -> 25000 | F7: =月度资金流!K7 -> 2209.3023 | G7: =月度资金流!N7 -> 0 | H7: =月度资金流!W7 -> 0 | I7: =月度资金流!Z7 -> 0 | J7: =月度资金流!O7 -> 0 | K7: =月度资金流!P7 -> 0 | L7: =月度资金流!Q7 -> 0 | M7: =月度资金流!R7 -> 0 | N7: =月度资金流!U7 -> 0 | O7: =月度资金流!AA7 -> 0 | P7: =月度资金流!AC7 -> 2209.3023 | Q7: =月度资金流!AD7 -> 2500 | R7: =月度资金流!AE7 -> 25000 | S7: =月度资金流!AF7 -> 23400 | T7: =月度资金流!AI7 -> 0
A8: =月度资金流!A8 -> 46266 | B8: =月度资金流!B8 -> 策略一：消费贷款+买基金 | C8: =IF(D8>0,"买入 "&ROUND(D8,0)&" 股，支付 HK$"&ROUND(E8,0)&"，找零 HK$"&ROUND(F8,0)&"；分红 HK$"&ROUND(G8,0),IF(H8>0,"卖出 "&ROUND(H8,0)&" 股，净收 HK$"&ROUND(I8,0)&"；内部池支付 HK$"&ROUND(N8,0)&"；分红 HK$"&ROUND(G8,0),IF(M8>0,"新贷款抵还 HK$"&ROUND(M8,0)&"；内部池支付 HK$"&ROUND(N8,0)&"；分红 HK$"&ROUND(G8,0),IF(L8>0,"应还 HK$"&ROUND(L8,0)&"；内部池支付 HK$"&ROUND(N8,0)&IF(O8>0,"；外部池投入 HK$"&ROUND(O8,0),"")&"；分红 HK$"&ROUND(G8,0),IF(G8>0,"收到分红 HK$"&ROUND(G8,0),"无需操作"))))) -> 买入 2500 股，支付 HK$25000，找零 HK$2209；分红 HK$125 | D8: =月度资金流!H8 -> 2500 | E8: =月度资金流!I8 -> 25000 | F8: =月度资金流!K8 -> 2209.3023 | G8: =月度资金流!N8 -> 125 | H8: =月度资金流!W8 -> 0 | I8: =月度资金流!Z8 -> 0 | J8: =月度资金流!O8 -> 0 | K8: =月度资金流!P8 -> 0 | L8: =月度资金流!Q8 -> 0 | M8: =月度资金流!R8 -> 0 | N8: =月度资金流!U8 -> 0 | O8: =月度资金流!AA8 -> 0 | P8: =月度资金流!AC8 -> 4543.6047 | Q8: =月度资金流!AD8 -> 5000 | R8: =月度资金流!AE8 -> 50000 | S8: =月度资金流!AF8 -> 46800 | T8: =月度资金流!AI8 -> 125
A9: =月度资金流!A9 -> 46296 | B9: =月度资金流!B9 -> 策略一：消费贷款+买基金 | C9: =IF(D9>0,"买入 "&ROUND(D9,0)&" 股，支付 HK$"&ROUND(E9,0)&"，找零 HK$"&ROUND(F9,0)&"；分红 HK$"&ROUND(G9,0),IF(H9>0,"卖出 "&ROUND(H9,0)&" 股，净收 HK$"&ROUND(I9,0)&"；内部池支付 HK$"&ROUND(N9,0)&"；分红 HK$"&ROUND(G9,0),IF(M9>0,"新贷款抵还 HK$"&ROUND(M9,0)&"；内部池支付 HK$"&ROUND(N9,0)&"；分红 HK$"&ROUND(G9,0),IF(L9>0,"应还 HK$"&ROUND(L9,0)&"；内部池支付 HK$"&ROUND(N9,0)&IF(O9>0,"；外部池投入 HK$"&ROUND(O9,0),"")&"；分红 HK$"&ROUND(G9,0),IF(G9>0,"收到分红 HK$"&ROUND(G9,0),"无需操作"))))) -> 买入 2500 股，支付 HK$25000，找零 HK$2209；分红 HK$250 | D9: =月度资金流!H9 -> 2500 | E9: =月度资金流!I9 -> 25000 | F9: =月度资金流!K9 -> 2209.3023 | G9: =月度资金流!N9 -> 250 | H9: =月度资金流!W9 -> 0 | I9: =月度资金流!Z9 -> 0 | J9: =月度资金流!O9 -> 0 | K9: =月度资金流!P9 -> 120.12 | L9: =月度资金流!Q9 -> 139.67442 | M9: =月度资金流!R9 -> 0 | N9: =月度资金流!U9 -> 139.67442 | O9: =月度资金流!AA9 -> 0 | P9: =月度资金流!AC9 -> 6863.2326 | Q9: =月度资金流!AD9 -> 7500 | R9: =月度资金流!AE9 -> 75000 | S9: =月度资金流!AF9 -> 70200 | T9: =月度资金流!AI9 -> 235.32558
A10: =月度资金流!A10 -> 46327 | B10: =月度资金流!B10 -> 策略一：消费贷款+买基金 | C10: =IF(D10>0,"买入 "&ROUND(D10,0)&" 股，支付 HK$"&ROUND(E10,0)&"，找零 HK$"&ROUND(F10,0)&"；分红 HK$"&ROUND(G10,0),IF(H10>0,"卖出 "&ROUND(H10,0)&" 股，净收 HK$"&ROUND(I10,0)&"；内部池支付 HK$"&ROUND(N10,0)&"；分红 HK$"&ROUND(G10,0),IF(M10>0,"新贷款抵还 HK$"&ROUND(M10,0)&"；内部池支付 HK$"&ROUND(N10,0)&"；分红 HK$"&ROUND(G10,0),IF(L10>0,"应还 HK$"&ROUND(L10,0)&"；内部池支付 HK$"&ROUND(N10,0)&IF(O10>0,"；外部池投入 HK$"&ROUND(O10,0),"")&"；分红 HK$"&ROUND(G10,0),IF(G10>0,"收到分红 HK$"&ROUND(G10,0),"无需操作"))))) -> 买入 2500 股，支付 HK$25000，找零 HK$2209；分红 HK$375 | D10: =月度资金流!H10 -> 2500 | E10: =月度资金流!I10 -> 25000 | F10: =月度资金流!K10 -> 2209.3023 | G10: =月度资金流!N10 -> 375 | H10: =月度资金流!W10 -> 0 | I10: =月度资金流!Z10 -> 0 | J10: =月度资金流!O10 -> 0 | K10: =月度资金流!P10 -> 186.62 | L10: =月度资金流!Q10 -> 217 | M10: =月度资金流!R10 -> 0 | N10: =月度资金流!U10 -> 217 | O10: =月度资金流!AA10 -> 0 | P10: =月度资金流!AC10 -> 9230.5349 | Q10: =月度资金流!AD10 -> 10000 | R10: =月度资金流!AE10 -> 100000 | S10: =月度资金流!AF10 -> 93600 | T10: =月度资金流!AI10 -> 393.32558
A11: =月度资金流!A11 -> 46357 | B11: =月度资金流!B11 -> 策略一：消费贷款+买基金 | C11: =IF(D11>0,"买入 "&ROUND(D11,0)&" 股，支付 HK$"&ROUND(E11,0)&"，找零 HK$"&ROUND(F11,0)&"；分红 HK$"&ROUND(G11,0),IF(H11>0,"卖出 "&ROUND(H11,0)&" 股，净收 HK$"&ROUND(I11,0)&"；内部池支付 HK$"&ROUND(N11,0)&"；分红 HK$"&ROUND(G11,0),IF(M11>0,"新贷款抵还 HK$"&ROUND(M11,0)&"；内部池支付 HK$"&ROUND(N11,0)&"；分红 HK$"&ROUND(G11,0),IF(L11>0,"应还 HK$"&ROUND(L11,0)&"；内部池支付 HK$"&ROUND(N11,0)&IF(O11>0,"；外部池投入 HK$"&ROUND(O11,0),"")&"；分红 HK$"&ROUND(G11,0),IF(G11>0,"收到分红 HK$"&ROUND(G11,0),"无需操作"))))) -> 买入 2500 股，支付 HK$25000，找零 HK$2209；分红 HK$500 | D11: =月度资金流!H11 -> 2500 | E11: =月度资金流!I11 -> 25000 | F11: =月度资金流!K11 -> 2209.3023 | G11: =月度资金流!N11 -> 500 | H11: =月度资金流!W11 -> 0 | I11: =月度资金流!Z11 -> 0 | J11: =月度资金流!O11 -> 0 | K11: =月度资金流!P11 -> 248.82 | L11: =月度资金流!Q11 -> 289.32558 | M11: =月度资金流!R11 -> 0 | N11: =月度资金流!U11 -> 289.32558 | O11: =月度资金流!AA11 -> 0 | P11: =月度资金流!AC11 -> 11650.512 | Q11: =月度资金流!AD11 -> 12500 | R11: =月度资金流!AE11 -> 125000 | S11: =月度资金流!AF11 -> 117000 | T11: =月度资金流!AI11 -> 604
A12: =月度资金流!A12 -> 46388 | B12: =月度资金流!B12 -> 策略一：消费贷款+买基金 | C12: =IF(D12>0,"买入 "&ROUND(D12,0)&" 股，支付 HK$"&ROUND(E12,0)&"，找零 HK$"&ROUND(F12,0)&"；分红 HK$"&ROUND(G12,0),IF(H12>0,"卖出 "&ROUND(H12,0)&" 股，净收 HK$"&ROUND(I12,0)&"；内部池支付 HK$"&ROUND(N12,0)&"；分红 HK$"&ROUND(G12,0),IF(M12>0,"新贷款抵还 HK$"&ROUND(M12,0)&"；内部池支付 HK$"&ROUND(N12,0)&"；分红 HK$"&ROUND(G12,0),IF(L12>0,"应还 HK$"&ROUND(L12,0)&"；内部池支付 HK$"&ROUND(N12,0)&IF(O12>0,"；外部池投入 HK$"&ROUND(O12,0),"")&"；分红 HK$"&ROUND(G12,0),IF(G12>0,"收到分红 HK$"&ROUND(G12,0),"无需操作"))))) -> 买入 2500 股，支付 HK$25000，找零 HK$2209；分红 HK$625 | D12: =月度资金流!H12 -> 2500 | E12: =月度资金流!I12 -> 25000 | F12: =月度资金流!K12 -> 2209.3023 | G12: =月度资金流!N12 -> 625 | H12: =月度资金流!W12 -> 0 | I12: =月度资金流!Z12 -> 0 | J12: =月度资金流!O12 -> 0 | K12: =月度资金流!P12 -> 319.62 | L12: =月度资金流!Q12 -> 371.65116 | M12: =月度资金流!R12 -> 0 | N12: =月度资金流!U12 -> 371.65116 | O12: =月度资金流!AA12 -> 0 | P12: =月度资金流!AC12 -> 14113.163 | Q12: =月度资金流!AD12 -> 15000 | R12: =月度资金流!AE12 -> 150000 | S12: =月度资金流!AF12 -> 140400 | T12: =月度资金流!AI12 -> 857.34884
A13: =月度资金流!A13 -> 46419 | B13: =月度资金流!B13 -> 策略一：消费贷款+买基金 | C13: =IF(D13>0,"买入 "&ROUND(D13,0)&" 股，支付 HK$"&ROUND(E13,0)&"，找零 HK$"&ROUND(F13,0)&"；分红 HK$"&ROUND(G13,0),IF(H13>0,"卖出 "&ROUND(H13,0)&" 股，净收 HK$"&ROUND(I13,0)&"；内部池支付 HK$"&ROUND(N13,0)&"；分红 HK$"&ROUND(G13,0),IF(M13>0,"新贷款抵还 HK$"&ROUND(M13,0)&"；内部池支付 HK$"&ROUND(N13,0)&"；分红 HK$"&ROUND(G13,0),IF(L13>0,"应还 HK$"&ROUND(L13,0)&"；内部池支付 HK$"&ROUND(N13,0)&IF(O13>0,"；外部池投入 HK$"&ROUND(O13,0),"")&"；分红 HK$"&ROUND(G13,0),IF(G13>0,"收到分红 HK$"&ROUND(G13,0),"无需操作"))))) -> 买入 2500 股，支付 HK$25000，找零 HK$2209；分红 HK$750 | D13: =月度资金流!H13 -> 2500 | E13: =月度资金流!I13 -> 25000 | F13: =月度资金流!K13 -> 2209.3023 | G13: =月度资金流!N13 -> 750 | H13: =月度资金流!W13 -> 0 | I13: =月度资金流!Z13 -> 0 | J13: =月度资金流!O13 -> 0 | K13: =月度资金流!P13 -> 388.27 | L13: =月度资金流!Q13 -> 451.47674 | M13: =月度资金流!R13 -> 0 | N13: =月度资金流!U13 -> 451.47674 | O13: =月度资金流!AA13 -> 0 | P13: =月度资金流!AC13 -> 16620.988 | Q13: =月度资金流!AD13 -> 17500 | R13: =月度资金流!AE13 -> 175000 | S13: =月度资金流!AF13 -> 163800 | T13: =月度资金流!AI13 -> 1155.8721
A14: =月度资金流!A14 -> 46447 | B14: =月度资金流!B14 -> 策略一：消费贷款+买基金 | C14: =IF(D14>0,"买入 "&ROUND(D14,0)&" 股，支付 HK$"&ROUND(E14,0)&"，找零 HK$"&ROUND(F14,0)&"；分红 HK$"&ROUND(G14,0),IF(H14>0,"卖出 "&ROUND(H14,0)&" 股，净收 HK$"&ROUND(I14,0)&"；内部池支付 HK$"&ROUND(N14,0)&"；分红 HK$"&ROUND(G14,0),IF(M14>0,"新贷款抵还 HK$"&ROUND(M14,0)&"；内部池支付 HK$"&ROUND(N14,0)&"；分红 HK$"&ROUND(G14,0),IF(L14>0,"应还 HK$"&ROUND(L14,0)&"；内部池支付 HK$"&ROUND(N14,0)&IF(O14>0,"；外部池投入 HK$"&ROUND(O14,0),"")&"；分红 HK$"&ROUND(G14,0),IF(G14>0,"收到分红 HK$"&ROUND(G14,0),"无需操作"))))) -> 买入 2500 股，支付 HK$25000，找零 HK$2209；分红 HK$875 | D14: =月度资金流!H14 -> 2500 | E14: =月度资金流!I14 -> 25000 | F14: =月度资金流!K14 -> 2209.3023 | G14: =月度资金流!N14 -> 875 | H14: =月度资金流!W14 -> 0 | I14: =月度资金流!Z14 -> 0 | J14: =月度资金流!O14 -> 0 | K14: =月度资金流!P14 -> 416.13 | L14: =月度资金流!Q14 -> 483.87209 | M14: =月度资金流!R14 -> 0 | N14: =月度资金流!U14 -> 483.87209 | O14: =月度资金流!AA14 -> 0 | P14: =月度资金流!AC14 -> 19221.419 | Q14: =月度资金流!AD14 -> 20000 | R14: =月度资金流!AE14 -> 200000 | S14: =月度资金流!AF14 -> 187200 | T14: =月度资金流!AI14 -> 1547
A15: =月度资金流!A15 -> 46478 | B15: =月度资金流!B15 -> 策略一：消费贷款+买基金 | C15: =IF(D15>0,"买入 "&ROUND(D15,0)&" 股，支付 HK$"&ROUND(E15,0)&"，找零 HK$"&ROUND(F15,0)&"；分红 HK$"&ROUND(G15,0),IF(H15>0,"卖出 "&ROUND(H15,0)&" 股，净收 HK$"&ROUND(I15,0)&"；内部池支付 HK$"&ROUND(N15,0)&"；分红 HK$"&ROUND(G15,0),IF(M15>0,"新贷款抵还 HK$"&ROUND(M15,0)&"；内部池支付 HK$"&ROUND(N15,0)&"；分红 HK$"&ROUND(G15,0),IF(L15>0,"应还 HK$"&ROUND(L15,0)&"；内部池支付 HK$"&ROUND(N15,0)&IF(O15>0,"；外部池投入 HK$"&ROUND(O15,0),"")&"；分红 HK$"&ROUND(G15,0),IF(G15>0,"收到分红 HK$"&ROUND(G15,0),"无需操作"))))) -> 买入 2500 股，支付 HK$25000，找零 HK$2209；分红 HK$1000 | D15: =月度资金流!H15 -> 2500 | E15: =月度资金流!I15 -> 25000 | F15: =月度资金流!K15 -> 2209.3023 | G15: =月度资金流!N15 -> 1000 | H15: =月度资金流!W15 -> 0 | I15: =月度资金流!Z15 -> 0 | J15: =月度资金流!O15 -> 0 | K15: =月度资金流!P15 -> 514.83 | L15: =月度资金流!Q15 -> 598.63953 | M15: =月度资金流!R15 -> 0 | N15: =月度资金流!U15 -> 598.63953 | O15: =月度资金流!AA15 -> 0 | P15: =月度资金流!AC15 -> 21832.081 | Q15: =月度资金流!AD15 -> 22500 | R15: =月度资金流!AE15 -> 225000 | S15: =月度资金流!AF15 -> 210600 | T15: =月度资金流!AI15 -> 1948.3605
A16: =月度资金流!A16 -> 46508 | B16: =月度资金流!B16 -> 策略一：消费贷款+买基金 | C16: =IF(D16>0,"买入 "&ROUND(D16,0)&" 股，支付 HK$"&ROUND(E16,0)&"，找零 HK$"&ROUND(F16,0)&"；分红 HK$"&ROUND(G16,0),IF(H16>0,"卖出 "&ROUND(H16,0)&" 股，净收 HK$"&ROUND(I16,0)&"；内部池支付 HK$"&ROUND(N16,0)&"；分红 HK$"&ROUND(G16,0),IF(M16>0,"新贷款抵还 HK$"&ROUND(M16,0)&"；内部池支付 HK$"&ROUND(N16,0)&"；分红 HK$"&ROUND(G16,0),IF(L16>0,"应还 HK$"&ROUND(L16,0)&"；内部池支付 HK$"&ROUND(N16,0)&IF(O16>0,"；外部池投入 HK$"&ROUND(O16,0),"")&"；分红 HK$"&ROUND(G16,0),IF(G16>0,"收到分红 HK$"&ROUND(G16,0),"无需操作"))))) -> 买入 2500 股，支付 HK$25000，找零 HK$2209；分红 HK$1125 | D16: =月度资金流!H16 -> 2500 | E16: =月度资金流!I16 -> 25000 | F16: =月度资金流!K16 -> 2209.3023 | G16: =月度资金流!N16 -> 1125 | H16: =月度资金流!W16 -> 0 | I16: =月度资金流!Z16 -> 0 | J16: =月度资金流!O16 -> 0 | K16: =月度资金流!P16 -> 570.57 | L16: =月度资金流!Q16 -> 663.45349 | M16: =月度资金流!R16 -> 0 | N16: =月度资金流!U16 -> 663.45349 | O16: =月度资金流!AA16 -> 0 | P16: =月度资金流!AC16 -> 24502.93 | Q16: =月度资金流!AD16 -> 25000 | R16: =月度资金流!AE16 -> 250000 | S16: =月度资金流!AF16 -> 234000 | T16: =月度资金流!AI16 -> 2409.907
A17: =月度资金流!A17 -> 46539 | B17: =月度资金流!B17 -> 策略一：消费贷款+买基金 | C17: =IF(D17>0,"买入 "&ROUND(D17,0)&" 股，支付 HK$"&ROUND(E17,0)&"，找零 HK$"&ROUND(F17,0)&"；分红 HK$"&ROUND(G17,0),IF(H17>0,"卖出 "&ROUND(H17,0)&" 股，净收 HK$"&ROUND(I17,0)&"；内部池支付 HK$"&ROUND(N17,0)&"；分红 HK$"&ROUND(G17,0),IF(M17>0,"新贷款抵还 HK$"&ROUND(M17,0)&"；内部池支付 HK$"&ROUND(N17,0)&"；分红 HK$"&ROUND(G17,0),IF(L17>0,"应还 HK$"&ROUND(L17,0)&"；内部池支付 HK$"&ROUND(N17,0)&IF(O17>0,"；外部池投入 HK$"&ROUND(O17,0),"")&"；分红 HK$"&ROUND(G17,0),IF(G17>0,"收到分红 HK$"&ROUND(G17,0),"无需操作"))))) -> 买入 2500 股，支付 HK$25000，找零 HK$2209；分红 HK$1250 | D17: =月度资金流!H17 -> 2500 | E17: =月度资金流!I17 -> 25000 | F17: =月度资金流!K17 -> 2209.3023 | G17: =月度资金流!N17 -> 1250 | H17: =月度资金流!W17 -> 0 | I17: =月度资金流!Z17 -> 0 | J17: =月度资金流!O17 -> 0 | K17: =月度资金流!P17 -> 652.12 | L17: =月度资金流!Q17 -> 758.27907 | M17: =月度资金流!R17 -> 0 | N17: =月度资金流!U17 -> 758.27907 | O17: =月度资金流!AA17 -> 0 | P17: =月度资金流!AC17 -> 27203.953 | Q17: =月度资金流!AD17 -> 27500 | R17: =月度资金流!AE17 -> 275000 | S17: =月度资金流!AF17 -> 257400 | T17: =月度资金流!AI17 -> 2901.6279
A18: =月度资金流!A18 -> 46569 | B18: =月度资金流!B18 -> 策略一：消费贷款+买基金 | C18: =IF(D18>0,"买入 "&ROUND(D18,0)&" 股，支付 HK$"&ROUND(E18,0)&"，找零 HK$"&ROUND(F18,0)&"；分红 HK$"&ROUND(G18,0),IF(H18>0,"卖出 "&ROUND(H18,0)&" 股，净收 HK$"&ROUND(I18,0)&"；内部池支付 HK$"&ROUND(N18,0)&"；分红 HK$"&ROUND(G18,0),IF(M18>0,"新贷款抵还 HK$"&ROUND(M18,0)&"；内部池支付 HK$"&ROUND(N18,0)&"；分红 HK$"&ROUND(G18,0),IF(L18>0,"应还 HK$"&ROUND(L18,0)&"；内部池支付 HK$"&ROUND(N18,0)&IF(O18>0,"；外部池投入 HK$"&ROUND(O18,0),"")&"；分红 HK$"&ROUND(G18,0),IF(G18>0,"收到分红 HK$"&ROUND(G18,0),"无需操作"))))) -> 买入 2500 股，支付 HK$25000，找零 HK$2209；分红 HK$1375 | D18: =月度资金流!H18 -> 2500 | E18: =月度资金流!I18 -> 25000 | F18: =月度资金流!K18 -> 2209.3023 | G18: =月度资金流!N18 -> 1375 | H18: =月度资金流!W18 -> 0 | I18: =月度资金流!Z18 -> 0 | J18: =月度资金流!O18 -> 0 | K18: =月度资金流!P18 -> 699.27 | L18: =月度资金流!Q18 -> 813.10465 | M18: =月度资金流!R18 -> 0 | N18: =月度资金流!U18 -> 813.10465 | O18: =月度资金流!AA18 -> 0 | P18: =月度资金流!AC18 -> 29975.151 | Q18: =月度资金流!AD18 -> 30000 | R18: =月度资金流!AE18 -> 300000 | S18: =月度资金流!AF18 -> 280800 | T18: =月度资金流!AI18 -> 3463.5233
... A54: =月度资金流!A54 -> 47665 | B54: =月度资金流!B54 -> 期后：内部池优先+外部池 | C54: =IF(D54>0,"买入 "&ROUND(D54,0)&" 股，支付 HK$"&ROUND(E54,0)&"，找零 HK$"&ROUND(F54,0)&"；分红 HK$"&ROUND(G54,0),IF(H54>0,"卖出 "&ROUND(H54,0)&" 股，净收 HK$"&ROUND(I54,0)&"；内部池支付 HK$"&ROUND(N54,0)&"；分红 HK$"&ROUND(G54,0),IF(M54>0,"新贷款抵还 HK$"&ROUND(M54,0)&"；内部池支付 HK$"&ROUND(N54,0)&"；分红 HK$"&ROUND(G54,0),IF(L54>0,"应还 HK$"&ROUND(L54,0)&"；内部池支付 HK$"&ROUND(N54,0)&IF(O54>0,"；外部池投入 HK$"&ROUND(O54,0),"")&"；分红 HK$"&ROUND(G54,0),IF(G54>0,"收到分红 HK$"&ROUND(G54,0),"无需操作"))))) -> 收到分红 HK$75 | D54: =月度资金流!H54 -> 0 | E54: =月度资金流!I54 -> 0 | F54: =月度资金流!K54 -> 0 | G54: =月度资金流!N54 -> 75 | H54: =月度资金流!W54 -> 0 | I54: =月度资金流!Z54 -> 0 | J54: =月度资金流!O54 -> 0 | K54: =月度资金流!P54 -> 0 | L54: =月度资金流!Q54 -> 0 | M54: =月度资金流!R54 -> 0 | N54: =月度资金流!U54 -> 0 | O54: =月度资金流!AA54 -> 0 | P54: =月度资金流!AC54 -> 2769.9535 | Q54: =月度资金流!AD54 -> 1500 | R54: =月度资金流!AE54 -> 15000 | S54: =月度资金流!AF54 -> 0 | T54: =月度资金流!AI54 -> 17769.953

Sheet 月度资金流
A1: 月度资金流与整手基金交易
A6: 月份 | B6: 当月策略 | C6: 新增贷款（人民币） | D6: 汇率 | E6: 可用港币 | F6: 单位价格 | G6: 每手股数 | H6: 买入股数 | I6: 基金买入金额 | J6: 申购费 | K6: 买入找零 | L6: 期初持仓 | M6: 当月应计分红 | N6: 当月收到分红 | O6: 应还本金（人民币） | P6: 应还利息（人民币） | Q6: 总还款（港币） | R6: 新贷款抵还 | S6: 内部池期初 | T6: 分红及找零后内部池 | U6: 内部池用于还款 | V6: 还款缺口 | W6: 卖出股数 | X6: 卖出毛额 | Y6: 赎回费 | Z6: 卖出净额 | AA6: 外部资金池投入 | AB6: 卖出超额入内部池 | AC6: 内部现金池期末 | AD6: 期末持仓 | AE6: 期末基金市值 | AF6: 期末未偿贷款（人民币） | AG6: 负债折港币 | AH6: 基金+内部池 | AI6: 策略净资产 | AJ6: 资金来源校验
A7: =EDATE(DATE(YEAR(参数设置!$B$4),MONTH(参数设置!$B$4),1),ROW()-7) -> 46235 | B7: 策略一：消费贷款+买基金 | C7: =IF(AND(ROW()-6<=参数设置!$B$6,OR(B7=策略字典!$A$1,B7=策略字典!$A$2)),参数设置!$B$5,0) -> 23400 | D7: =参数设置!$B$7 -> 0.86 | E7: =IF(B7=策略字典!$A$1,C7/D7,0) -> 27209.302 | F7: =参数设置!$B$18 -> 10 | G7: =参数设置!$B$19 -> 500 | H7: =IF(E7=0,0,FLOOR(E7/(F7*(1+参数设置!$B$22)),G7)) -> 2500 | I7: =H7*F7 -> 25000 | J7: =I7*参数设置!$B$22 -> 0 | K7: =MAX(0,E7-I7-J7) -> 2209.3023 | L7: =IF(ROW()=7,0,AD6) -> 0 | M7: =(L7+H7)*参数设置!$B$20 -> 125 | N7: =0 -> 0 | O7: =SUMIFS(贷款明细!$I$4:$I$435,贷款明细!$G$4:$G$435,">="&A7,贷款明细!$G$4:$G$435,"<"&EDATE(A7,1)) -> 0 | P7: =SUMIFS(贷款明细!$J$4:$J$435,贷款明细!$G$4:$G$435,">="&A7,贷款明细!$G$4:$G$435,"<"&EDATE(A7,1)) -> 0 | Q7: =(O7+P7)/D7 -> 0 | R7: =IF(B7=策略字典!$A$2,MIN(C7,O7)/D7,0) -> 0 | S7: =IF(ROW()=7,0,AC6) -> 0 | T7: =S7+N7+K7 -> 2209.3023 | U7: =MIN(T7,MAX(0,Q7-R7)) -> 0 | V7: =MAX(0,Q7-R7-U7) -> 0 | W7: =IF(B7=策略字典!$A$3,MIN(L7+H7,CEILING(V7/(F7*(1-参数设置!$B$23)),G7)),0) -> 0 | X7: =W7*F7 -> 0 | Y7: =X7*参数设置!$B$23 -> 0 | Z7: =X7-Y7 -> 0 | AA7: =MAX(0,V7-Z7) -> 0 | AB7: =MAX(0,Z7-V7) -> 0 | AC7: =T7-U7+AB7 -> 2209.3023 | AD7: =MAX(0,L7+H7-W7) -> 2500 | AE7: =AD7*F7 -> 25000 | AF7: =SUM($C$7:C7)-SUM($O$7:O7) -> 23400 | AG7: =AF7/D7 -> 27209.302 | AH7: =AE7+AC7 -> 27209.302 | AI7: =AH7-AG7-SUM($AA$7:AA7) -> 0 | AJ7: =R7+U7+MIN(Z7,V7)+AA7-Q7 -> 0
A8: =EDATE(DATE(YEAR(参数设置!$B$4),MONTH(参数设置!$B$4),1),ROW()-7) -> 46266 | B8: 策略一：消费贷款+买基金 | C8: =IF(AND(ROW()-6<=参数设置!$B$6,OR(B8=策略字典!$A$1,B8=策略字典!$A$2)),参数设置!$B$5,0) -> 23400 | D8: =参数设置!$B$7 -> 0.86 | E8: =IF(B8=策略字典!$A$1,C8/D8,0) -> 27209.302 | F8: =参数设置!$B$18 -> 10 | G8: =参数设置!$B$19 -> 500 | H8: =IF(E8=0,0,FLOOR(E8/(F8*(1+参数设置!$B$22)),G8)) -> 2500 | I8: =H8*F8 -> 25000 | J8: =I8*参数设置!$B$22 -> 0 | K8: =MAX(0,E8-I8-J8) -> 2209.3023 | L8: =IF(ROW()=7,0,AD7) -> 2500 | M8: =(L8+H8)*参数设置!$B$20 -> 250 | N8: =M7 -> 125 | O8: =SUMIFS(贷款明细!$I$4:$I$435,贷款明细!$G$4:$G$435,">="&A8,贷款明细!$G$4:$G$435,"<"&EDATE(A8,1)) -> 0 | P8: =SUMIFS(贷款明细!$J$4:$J$435,贷款明细!$G$4:$G$435,">="&A8,贷款明细!$G$4:$G$435,"<"&EDATE(A8,1)) -> 0 | Q8: =(O8+P8)/D8 -> 0 | R8: =IF(B8=策略字典!$A$2,MIN(C8,O8)/D8,0) -> 0 | S8: =IF(ROW()=7,0,AC7) -> 2209.3023 | T8: =S8+N8+K8 -> 4543.6047 | U8: =MIN(T8,MAX(0,Q8-R8)) -> 0 | V8: =MAX(0,Q8-R8-U8) -> 0 | W8: =IF(B8=策略字典!$A$3,MIN(L8+H8,CEILING(V8/(F8*(1-参数设置!$B$23)),G8)),0) -> 0 | X8: =W8*F8 -> 0 | Y8: =X8*参数设置!$B$23 -> 0 | Z8: =X8-Y8 -> 0 | AA8: =MAX(0,V8-Z8) -> 0 | AB8: =MAX(0,Z8-V8) -> 0 | AC8: =T8-U8+AB8 -> 4543.6047 | AD8: =MAX(0,L8+H8-W8) -> 5000 | AE8: =AD8*F8 -> 50000 | AF8: =SUM($C$7:C8)-SUM($O$7:O8) -> 46800 | AG8: =AF8/D8 -> 54418.605 | AH8: =AE8+AC8 -> 54543.605 | AI8: =AH8-AG8-SUM($AA$7:AA8) -> 125 | AJ8: =R8+U8+MIN(Z8,V8)+AA8-Q8 -> 0
A9: =EDATE(DATE(YEAR(参数设置!$B$4),MONTH(参数设置!$B$4),1),ROW()-7) -> 46296 | B9: 策略一：消费贷款+买基金 | C9: =IF(AND(ROW()-6<=参数设置!$B$6,OR(B9=策略字典!$A$1,B9=策略字典!$A$2)),参数设置!$B$5,0) -> 23400 | D9: =参数设置!$B$7 -> 0.86 | E9: =IF(B9=策略字典!$A$1,C9/D9,0) -> 27209.302 | F9: =参数设置!$B$18 -> 10 | G9: =参数设置!$B$19 -> 500 | H9: =IF(E9=0,0,FLOOR(E9/(F9*(1+参数设置!$B$22)),G9)) -> 2500 | I9: =H9*F9 -> 25000 | J9: =I9*参数设置!$B$22 -> 0 | K9: =MAX(0,E9-I9-J9) -> 2209.3023 | L9: =IF(ROW()=7,0,AD8) -> 5000 | M9: =(L9+H9)*参数设置!$B$20 -> 375 | N9: =M8 -> 250 | O9: =SUMIFS(贷款明细!$I$4:$I$435,贷款明细!$G$4:$G$435,">="&A9,贷款明细!$G$4:$G$435,"<"&EDATE(A9,1)) -> 0 | P9: =SUMIFS(贷款明细!$J$4:$J$435,贷款明细!$G$4:$G$435,">="&A9,贷款明细!$G$4:$G$435,"<"&EDATE(A9,1)) -> 120.12 | Q9: =(O9+P9)/D9 -> 139.67442 | R9: =IF(B9=策略字典!$A$2,MIN(C9,O9)/D9,0) -> 0 | S9: =IF(ROW()=7,0,AC8) -> 4543.6047 | T9: =S9+N9+K9 -> 7002.907 | U9: =MIN(T9,MAX(0,Q9-R9)) -> 139.67442 | V9: =MAX(0,Q9-R9-U9) -> 0 | W9: =IF(B9=策略字典!$A$3,MIN(L9+H9,CEILING(V9/(F9*(1-参数设置!$B$23)),G9)),0) -> 0 | X9: =W9*F9 -> 0 | Y9: =X9*参数设置!$B$23 -> 0 | Z9: =X9-Y9 -> 0 | AA9: =MAX(0,V9-Z9) -> 0 | AB9: =MAX(0,Z9-V9) -> 0 | AC9: =T9-U9+AB9 -> 6863.2326 | AD9: =MAX(0,L9+H9-W9) -> 7500 | AE9: =AD9*F9 -> 75000 | AF9: =SUM($C$7:C9)-SUM($O$7:O9) -> 70200 | AG9: =AF9/D9 -> 81627.907 | AH9: =AE9+AC9 -> 81863.233 | AI9: =AH9-AG9-SUM($AA$7:AA9) -> 235.32558 | AJ9: =R9+U9+MIN(Z9,V9)+AA9-Q9 -> 0
A10: =EDATE(DATE(YEAR(参数设置!$B$4),MONTH(参数设置!$B$4),1),ROW()-7) -> 46327 | B10: 策略一：消费贷款+买基金 | C10: =IF(AND(ROW()-6<=参数设置!$B$6,OR(B10=策略字典!$A$1,B10=策略字典!$A$2)),参数设置!$B$5,0) -> 23400 | D10: =参数设置!$B$7 -> 0.86 | E10: =IF(B10=策略字典!$A$1,C10/D10,0) -> 27209.302 | F10: =参数设置!$B$18 -> 10 | G10: =参数设置!$B$19 -> 500 | H10: =IF(E10=0,0,FLOOR(E10/(F10*(1+参数设置!$B$22)),G10)) -> 2500 | I10: =H10*F10 -> 25000 | J10: =I10*参数设置!$B$22 -> 0 | K10: =MAX(0,E10-I10-J10) -> 2209.3023 | L10: =IF(ROW()=7,0,AD9) -> 7500 | M10: =(L10+H10)*参数设置!$B$20 -> 500 | N10: =M9 -> 375 | O10: =SUMIFS(贷款明细!$I$4:$I$435,贷款明细!$G$4:$G$435,">="&A10,贷款明细!$G$4:$G$435,"<"&EDATE(A10,1)) -> 0 | P10: =SUMIFS(贷款明细!$J$4:$J$435,贷款明细!$G$4:$G$435,">="&A10,贷款明细!$G$4:$G$435,"<"&EDATE(A10,1)) -> 186.62 | Q10: =(O10+P10)/D10 -> 217 | R10: =IF(B10=策略字典!$A$2,MIN(C10,O10)/D10,0) -> 0 | S10: =IF(ROW()=7,0,AC9) -> 6863.2326 | T10: =S10+N10+K10 -> 9447.5349 | U10: =MIN(T10,MAX(0,Q10-R10)) -> 217 | V10: =MAX(0,Q10-R10-U10) -> 0 | W10: =IF(B10=策略字典!$A$3,MIN(L10+H10,CEILING(V10/(F10*(1-参数设置!$B$23)),G10)),0) -> 0 | X10: =W10*F10 -> 0 | Y10: =X10*参数设置!$B$23 -> 0 | Z10: =X10-Y10 -> 0 | AA10: =MAX(0,V10-Z10) -> 0 | AB10: =MAX(0,Z10-V10) -> 0 | AC10: =T10-U10+AB10 -> 9230.5349 | AD10: =MAX(0,L10+H10-W10) -> 10000 | AE10: =AD10*F10 -> 100000 | AF10: =SUM($C$7:C10)-SUM($O$7:O10) -> 93600 | AG10: =AF10/D10 -> 108837.21 | AH10: =AE10+AC10 -> 109230.53 | AI10: =AH10-AG10-SUM($AA$7:AA10) -> 393.32558 | AJ10: =R10+U10+MIN(Z10,V10)+AA10-Q10 -> 0
A11: =EDATE(DATE(YEAR(参数设置!$B$4),MONTH(参数设置!$B$4),1),ROW()-7) -> 46357 | B11: 策略一：消费贷款+买基金 | C11: =IF(AND(ROW()-6<=参数设置!$B$6,OR(B11=策略字典!$A$1,B11=策略字典!$A$2)),参数设置!$B$5,0) -> 23400 | D11: =参数设置!$B$7 -> 0.86 | E11: =IF(B11=策略字典!$A$1,C11/D11,0) -> 27209.302 | F11: =参数设置!$B$18 -> 10 | G11: =参数设置!$B$19 -> 500 | H11: =IF(E11=0,0,FLOOR(E11/(F11*(1+参数设置!$B$22)),G11)) -> 2500 | I11: =H11*F11 -> 25000 | J11: =I11*参数设置!$B$22 -> 0 | K11: =MAX(0,E11-I11-J11) -> 2209.3023 | L11: =IF(ROW()=7,0,AD10) -> 10000 | M11: =(L11+H11)*参数设置!$B$20 -> 625 | N11: =M10 -> 500 | O11: =SUMIFS(贷款明细!$I$4:$I$435,贷款明细!$G$4:$G$435,">="&A11,贷款明细!$G$4:$G$435,"<"&EDATE(A11,1)) -> 0 | P11: =SUMIFS(贷款明细!$J$4:$J$435,贷款明细!$G$4:$G$435,">="&A11,贷款明细!$G$4:$G$435,"<"&EDATE(A11,1)) -> 248.82 | Q11: =(O11+P11)/D11 -> 289.32558 | R11: =IF(B11=策略字典!$A$2,MIN(C11,O11)/D11,0) -> 0 | S11: =IF(ROW()=7,0,AC10) -> 9230.5349 | T11: =S11+N11+K11 -> 11939.837 | U11: =MIN(T11,MAX(0,Q11-R11)) -> 289.32558 | V11: =MAX(0,Q11-R11-U11) -> 0 | W11: =IF(B11=策略字典!$A$3,MIN(L11+H11,CEILING(V11/(F11*(1-参数设置!$B$23)),G11)),0) -> 0 | X11: =W11*F11 -> 0 | Y11: =X11*参数设置!$B$23 -> 0 | Z11: =X11-Y11 -> 0 | AA11: =MAX(0,V11-Z11) -> 0 | AB11: =MAX(0,Z11-V11) -> 0 | AC11: =T11-U11+AB11 -> 11650.512 | AD11: =MAX(0,L11+H11-W11) -> 12500 | AE11: =AD11*F11 -> 125000 | AF11: =SUM($C$7:C11)-SUM($O$7:O11) -> 117000 | AG11: =AF11/D11 -> 136046.51 | AH11: =AE11+AC11 -> 136650.51 | AI11: =AH11-AG11-SUM($AA$7:AA11) -> 604 | AJ11: =R11+U11+MIN(Z11,V11)+AA11-Q11 -> 0
A12: =EDATE(DATE(YEAR(参数设置!$B$4),MONTH(参数设置!$B$4),1),ROW()-7) -> 46388 | B12: 策略一：消费贷款+买基金 | C12: =IF(AND(ROW()-6<=参数设置!$B$6,OR(B12=策略字典!$A$1,B12=策略字典!$A$2)),参数设置!$B$5,0) -> 23400 | D12: =参数设置!$B$7 -> 0.86 | E12: =IF(B12=策略字典!$A$1,C12/D12,0) -> 27209.302 | F12: =参数设置!$B$18 -> 10 | G12: =参数设置!$B$19 -> 500 | H12: =IF(E12=0,0,FLOOR(E12/(F12*(1+参数设置!$B$22)),G12)) -> 2500 | I12: =H12*F12 -> 25000 | J12: =I12*参数设置!$B$22 -> 0 | K12: =MAX(0,E12-I12-J12) -> 2209.3023 | L12: =IF(ROW()=7,0,AD11) -> 12500 | M12: =(L12+H12)*参数设置!$B$20 -> 750 | N12: =M11 -> 625 | O12: =SUMIFS(贷款明细!$I$4:$I$435,贷款明细!$G$4:$G$435,">="&A12,贷款明细!$G$4:$G$435,"<"&EDATE(A12,1)) -> 0 | P12: =SUMIFS(贷款明细!$J$4:$J$435,贷款明细!$G$4:$G$435,">="&A12,贷款明细!$G$4:$G$435,"<"&EDATE(A12,1)) -> 319.62 | Q12: =(O12+P12)/D12 -> 371.65116 | R12: =IF(B12=策略字典!$A$2,MIN(C12,O12)/D12,0) -> 0 | S12: =IF(ROW()=7,0,AC11) -> 11650.512 | T12: =S12+N12+K12 -> 14484.814 | U12: =MIN(T12,MAX(0,Q12-R12)) -> 371.65116 | V12: =MAX(0,Q12-R12-U12) -> 0 | W12: =IF(B12=策略字典!$A$3,MIN(L12+H12,CEILING(V12/(F12*(1-参数设置!$B$23)),G12)),0) -> 0 | X12: =W12*F12 -> 0 | Y12: =X12*参数设置!$B$23 -> 0 | Z12: =X12-Y12 -> 0 | AA12: =MAX(0,V12-Z12) -> 0 | AB12: =MAX(0,Z12-V12) -> 0 | AC12: =T12-U12+AB12 -> 14113.163 | AD12: =MAX(0,L12+H12-W12) -> 15000 | AE12: =AD12*F12 -> 150000 | AF12: =SUM($C$7:C12)-SUM($O$7:O12) -> 140400 | AG12: =AF12/D12 -> 163255.81 | AH12: =AE12+AC12 -> 164113.16 | AI12: =AH12-AG12-SUM($AA$7:AA12) -> 857.34884 | AJ12: =R12+U12+MIN(Z12,V12)+AA12-Q12 -> 0
A13: =EDATE(DATE(YEAR(参数设置!$B$4),MONTH(参数设置!$B$4),1),ROW()-7) -> 46419 | B13: 策略一：消费贷款+买基金 | C13: =IF(AND(ROW()-6<=参数设置!$B$6,OR(B13=策略字典!$A$1,B13=策略字典!$A$2)),参数设置!$B$5,0) -> 23400 | D13: =参数设置!$B$7 -> 0.86 | E13: =IF(B13=策略字典!$A$1,C13/D13,0) -> 27209.302 | F13: =参数设置!$B$18 -> 10 | G13: =参数设置!$B$19 -> 500 | H13: =IF(E13=0,0,FLOOR(E13/(F13*(1+参数设置!$B$22)),G13)) -> 2500 | I13: =H13*F13 -> 25000 | J13: =I13*参数设置!$B$22 -> 0 | K13: =MAX(0,E13-I13-J13) -> 2209.3023 | L13: =IF(ROW()=7,0,AD12) -> 15000 | M13: =(L13+H13)*参数设置!$B$20 -> 875 | N13: =M12 -> 750 | O13: =SUMIFS(贷款明细!$I$4:$I$435,贷款明细!$G$4:$G$435,">="&A13,贷款明细!$G$4:$G$435,"<"&EDATE(A13,1)) -> 0 | P13: =SUMIFS(贷款明细!$J$4:$J$435,贷款明细!$G$4:$G$435,">="&A13,贷款明细!$G$4:$G$435,"<"&EDATE(A13,1)) -> 388.27 | Q13: =(O13+P13)/D13 -> 451.47674 | R13: =IF(B13=策略字典!$A$2,MIN(C13,O13)/D13,0) -> 0 | S13: =IF(ROW()=7,0,AC12) -> 14113.163 | T13: =S13+N13+K13 -> 17072.465 | U13: =MIN(T13,MAX(0,Q13-R13)) -> 451.47674 | V13: =MAX(0,Q13-R13-U13) -> 0 | W13: =IF(B13=策略字典!$A$3,MIN(L13+H13,CEILING(V13/(F13*(1-参数设置!$B$23)),G13)),0) -> 0 | X13: =W13*F13 -> 0 | Y13: =X13*参数设置!$B$23 -> 0 | Z13: =X13-Y13 -> 0 | AA13: =MAX(0,V13-Z13) -> 0 | AB13: =MAX(0,Z13-V13) -> 0 | AC13: =T13-U13+AB13 -> 16620.988 | AD13: =MAX(0,L13+H13-W13) -> 17500 | AE13: =AD13*F13 -> 175000 | AF13: =SUM($C$7:C13)-SUM($O$7:O13) -> 163800 | AG13: =AF13/D13 -> 190465.12 | AH13: =AE13+AC13 -> 191620.99 | AI13: =AH13-AG13-SUM($AA$7:AA13) -> 1155.8721 | AJ13: =R13+U13+MIN(Z13,V13)+AA13-Q13 -> 0
A14: =EDATE(DATE(YEAR(参数设置!$B$4),MONTH(参数设置!$B$4),1),ROW()-7) -> 46447 | B14: 策略一：消费贷款+买基金 | C14: =IF(AND(ROW()-6<=参数设置!$B$6,OR(B14=策略字典!$A$1,B14=策略字典!$A$2)),参数设置!$B$5,0) -> 23400 | D14: =参数设置!$B$7 -> 0.86 | E14: =IF(B14=策略字典!$A$1,C14/D14,0) -> 27209.302 | F14: =参数设置!$B$18 -> 10 | G14: =参数设置!$B$19 -> 500 | H14: =IF(E14=0,0,FLOOR(E14/(F14*(1+参数设置!$B$22)),G14)) -> 2500 | I14: =H14*F14 -> 25000 | J14: =I14*参数设置!$B$22 -> 0 | K14: =MAX(0,E14-I14-J14) -> 2209.3023 | L14: =IF(ROW()=7,0,AD13) -> 17500 | M14: =(L14+H14)*参数设置!$B$20 -> 1000 | N14: =M13 -> 875 | O14: =SUMIFS(贷款明细!$I$4:$I$435,贷款明细!$G$4:$G$435,">="&A14,贷款明细!$G$4:$G$435,"<"&EDATE(A14,1)) -> 0 | P14: =SUMIFS(贷款明细!$J$4:$J$435,贷款明细!$G$4:$G$435,">="&A14,贷款明细!$G$4:$G$435,"<"&EDATE(A14,1)) -> 416.13 | Q14: =(O14+P14)/D14 -> 483.87209 | R14: =IF(B14=策略字典!$A$2,MIN(C14,O14)/D14,0) -> 0 | S14: =IF(ROW()=7,0,AC13) -> 16620.988 | T14: =S14+N14+K14 -> 19705.291 | U14: =MIN(T14,MAX(0,Q14-R14)) -> 483.87209 | V14: =MAX(0,Q14-R14-U14) -> 0 | W14: =IF(B14=策略字典!$A$3,MIN(L14+H14,CEILING(V14/(F14*(1-参数设置!$B$23)),G14)),0) -> 0 | X14: =W14*F14 -> 0 | Y14: =X14*参数设置!$B$23 -> 0 | Z14: =X14-Y14 -> 0 | AA14: =MAX(0,V14-Z14) -> 0 | AB14: =MAX(0,Z14-V14) -> 0 | AC14: =T14-U14+AB14 -> 19221.419 | AD14: =MAX(0,L14+H14-W14) -> 20000 | AE14: =AD14*F14 -> 200000 | AF14: =SUM($C$7:C14)-SUM($O$7:O14) -> 187200 | AG14: =AF14/D14 -> 217674.42 | AH14: =AE14+AC14 -> 219221.42 | AI14: =AH14-AG14-SUM($AA$7:AA14) -> 1547 | AJ14: =R14+U14+MIN(Z14,V14)+AA14-Q14 -> 0
A15: =EDATE(DATE(YEAR(参数设置!$B$4),MONTH(参数设置!$B$4),1),ROW()-7) -> 46478 | B15: 策略一：消费贷款+买基金 | C15: =IF(AND(ROW()-6<=参数设置!$B$6,OR(B15=策略字典!$A$1,B15=策略字典!$A$2)),参数设置!$B$5,0) -> 23400 | D15: =参数设置!$B$7 -> 0.86 | E15: =IF(B15=策略字典!$A$1,C15/D15,0) -> 27209.302 | F15: =参数设置!$B$18 -> 10 | G15: =参数设置!$B$19 -> 500 | H15: =IF(E15=0,0,FLOOR(E15/(F15*(1+参数设置!$B$22)),G15)) -> 2500 | I15: =H15*F15 -> 25000 | J15: =I15*参数设置!$B$22 -> 0 | K15: =MAX(0,E15-I15-J15) -> 2209.3023 | L15: =IF(ROW()=7,0,AD14) -> 20000 | M15: =(L15+H15)*参数设置!$B$20 -> 1125 | N15: =M14 -> 1000 | O15: =SUMIFS(贷款明细!$I$4:$I$435,贷款明细!$G$4:$G$435,">="&A15,贷款明细!$G$4:$G$435,"<"&EDATE(A15,1)) -> 0 | P15: =SUMIFS(贷款明细!$J$4:$J$435,贷款明细!$G$4:$G$435,">="&A15,贷款明细!$G$4:$G$435,"<"&EDATE(A15,1)) -> 514.83 | Q15: =(O15+P15)/D15 -> 598.63953 | R15: =IF(B15=策略字典!$A$2,MIN(C15,O15)/D15,0) -> 0 | S15: =IF(ROW()=7,0,AC14) -> 19221.419 | T15: =S15+N15+K15 -> 22430.721 | U15: =MIN(T15,MAX(0,Q15-R15)) -> 598.63953 | V15: =MAX(0,Q15-R15-U15) -> 0 | W15: =IF(B15=策略字典!$A$3,MIN(L15+H15,CEILING(V15/(F15*(1-参数设置!$B$23)),G15)),0) -> 0 | X15: =W15*F15 -> 0 | Y15: =X15*参数设置!$B$23 -> 0 | Z15: =X15-Y15 -> 0 | AA15: =MAX(0,V15-Z15) -> 0 | AB15: =MAX(0,Z15-V15) -> 0 | AC15: =T15-U15+AB15 -> 21832.081 | AD15: =MAX(0,L15+H15-W15) -> 22500 | AE15: =AD15*F15 -> 225000 | AF15: =SUM($C$7:C15)-SUM($O$7:O15) -> 210600 | AG15: =AF15/D15 -> 244883.72 | AH15: =AE15+AC15 -> 246832.08 | AI15: =AH15-AG15-SUM($AA$7:AA15) -> 1948.3605 | AJ15: =R15+U15+MIN(Z15,V15)+AA15-Q15 -> 0
A16: =EDATE(DATE(YEAR(参数设置!$B$4),MONTH(参数设置!$B$4),1),ROW()-7) -> 46508 | B16: 策略一：消费贷款+买基金 | C16: =IF(AND(ROW()-6<=参数设置!$B$6,OR(B16=策略字典!$A$1,B16=策略字典!$A$2)),参数设置!$B$5,0) -> 23400 | D16: =参数设置!$B$7 -> 0.86 | E16: =IF(B16=策略字典!$A$1,C16/D16,0) -> 27209.302 | F16: =参数设置!$B$18 -> 10 | G16: =参数设置!$B$19 -> 500 | H16: =IF(E16=0,0,FLOOR(E16/(F16*(1+参数设置!$B$22)),G16)) -> 2500 | I16: =H16*F16 -> 25000 | J16: =I16*参数设置!$B$22 -> 0 | K16: =MAX(0,E16-I16-J16) -> 2209.3023 | L16: =IF(ROW()=7,0,AD15) -> 22500 | M16: =(L16+H16)*参数设置!$B$20 -> 1250 | N16: =M15 -> 1125 | O16: =SUMIFS(贷款明细!$I$4:$I$435,贷款明细!$G$4:$G$435,">="&A16,贷款明细!$G$4:$G$435,"<"&EDATE(A16,1)) -> 0 | P16: =SUMIFS(贷款明细!$J$4:$J$435,贷款明细!$G$4:$G$435,">="&A16,贷款明细!$G$4:$G$435,"<"&EDATE(A16,1)) -> 570.57 | Q16: =(O16+P16)/D16 -> 663.45349 | R16: =IF(B16=策略字典!$A$2,MIN(C16,O16)/D16,0) -> 0 | S16: =IF(ROW()=7,0,AC15) -> 21832.081 | T16: =S16+N16+K16 -> 25166.384 | U16: =MIN(T16,MAX(0,Q16-R16)) -> 663.45349 | V16: =MAX(0,Q16-R16-U16) -> 0 | W16: =IF(B16=策略字典!$A$3,MIN(L16+H16,CEILING(V16/(F16*(1-参数设置!$B$23)),G16)),0) -> 0 | X16: =W16*F16 -> 0 | Y16: =X16*参数设置!$B$23 -> 0 | Z16: =X16-Y16 -> 0 | AA16: =MAX(0,V16-Z16) -> 0 | AB16: =MAX(0,Z16-V16) -> 0 | AC16: =T16-U16+AB16 -> 24502.93 | AD16: =MAX(0,L16+H16-W16) -> 25000 | AE16: =AD16*F16 -> 250000 | AF16: =SUM($C$7:C16)-SUM($O$7:O16) -> 234000 | AG16: =AF16/D16 -> 272093.02 | AH16: =AE16+AC16 -> 274502.93 | AI16: =AH16-AG16-SUM($AA$7:AA16) -> 2409.907 | AJ16: =R16+U16+MIN(Z16,V16)+AA16-Q16 -> 0
A17: =EDATE(DATE(YEAR(参数设置!$B$4),MONTH(参数设置!$B$4),1),ROW()-7) -> 46539 | B17: 策略一：消费贷款+买基金 | C17: =IF(AND(ROW()-6<=参数设置!$B$6,OR(B17=策略字典!$A$1,B17=策略字典!$A$2)),参数设置!$B$5,0) -> 23400 | D17: =参数设置!$B$7 -> 0.86 | E17: =IF(B17=策略字典!$A$1,C17/D17,0) -> 27209.302 | F17: =参数设置!$B$18 -> 10 | G17: =参数设置!$B$19 -> 500 | H17: =IF(E17=0,0,FLOOR(E17/(F17*(1+参数设置!$B$22)),G17)) -> 2500 | I17: =H17*F17 -> 25000 | J17: =I17*参数设置!$B$22 -> 0 | K17: =MAX(0,E17-I17-J17) -> 2209.3023 | L17: =IF(ROW()=7,0,AD16) -> 25000 | M17: =(L17+H17)*参数设置!$B$20 -> 1375 | N17: =M16 -> 1250 | O17: =SUMIFS(贷款明细!$I$4:$I$435,贷款明细!$G$4:$G$435,">="&A17,贷款明细!$G$4:$G$435,"<"&EDATE(A17,1)) -> 0 | P17: =SUMIFS(贷款明细!$J$4:$J$435,贷款明细!$G$4:$G$435,">="&A17,贷款明细!$G$4:$G$435,"<"&EDATE(A17,1)) -> 652.12 | Q17: =(O17+P17)/D17 -> 758.27907 | R17: =IF(B17=策略字典!$A$2,MIN(C17,O17)/D17,0) -> 0 | S17: =IF(ROW()=7,0,AC16) -> 24502.93 | T17: =S17+N17+K17 -> 27962.233 | U17: =MIN(T17,MAX(0,Q17-R17)) -> 758.27907 | V17: =MAX(0,Q17-R17-U17) -> 0 | W17: =IF(B17=策略字典!$A$3,MIN(L17+H17,CEILING(V17/(F17*(1-参数设置!$B$23)),G17)),0) -> 0 | X17: =W17*F17 -> 0 | Y17: =X17*参数设置!$B$23 -> 0 | Z17: =X17-Y17 -> 0 | AA17: =MAX(0,V17-Z17) -> 0 | AB17: =MAX(0,Z17-V17) -> 0 | AC17: =T17-U17+AB17 -> 27203.953 | AD17: =MAX(0,L17+H17-W17) -> 27500 | AE17: =AD17*F17 -> 275000 | AF17: =SUM($C$7:C17)-SUM($O$7:O17) -> 257400 | AG17: =AF17/D17 -> 299302.33 | AH17: =AE17+AC17 -> 302203.95 | AI17: =AH17-AG17-SUM($AA$7:AA17) -> 2901.6279 | AJ17: =R17+U17+MIN(Z17,V17)+AA17-Q17 -> 0
A18: =EDATE(DATE(YEAR(参数设置!$B$4),MONTH(参数设置!$B$4),1),ROW()-7) -> 46569 | B18: 策略一：消费贷款+买基金 | C18: =IF(AND(ROW()-6<=参数设置!$B$6,OR(B18=策略字典!$A$1,B18=策略字典!$A$2)),参数设置!$B$5,0) -> 23400 | D18: =参数设置!$B$7 -> 0.86 | E18: =IF(B18=策略字典!$A$1,C18/D18,0) -> 27209.302 | F18: =参数设置!$B$18 -> 10 | G18: =参数设置!$B$19 -> 500 | H18: =IF(E18=0,0,FLOOR(E18/(F18*(1+参数设置!$B$22)),G18)) -> 2500 | I18: =H18*F18 -> 25000 | J18: =I18*参数设置!$B$22 -> 0 | K18: =MAX(0,E18-I18-J18) -> 2209.3023 | L18: =IF(ROW()=7,0,AD17) -> 27500 | M18: =(L18+H18)*参数设置!$B$20 -> 1500 | N18: =M17 -> 1375 | O18: =SUMIFS(贷款明细!$I$4:$I$435,贷款明细!$G$4:$G$435,">="&A18,贷款明细!$G$4:$G$435,"<"&EDATE(A18,1)) -> 0 | P18: =SUMIFS(贷款明细!$J$4:$J$435,贷款明细!$G$4:$G$435,">="&A18,贷款明细!$G$4:$G$435,"<"&EDATE(A18,1)) -> 699.27 | Q18: =(O18+P18)/D18 -> 813.10465 | R18: =IF(B18=策略字典!$A$2,MIN(C18,O18)/D18,0) -> 0 | S18: =IF(ROW()=7,0,AC17) -> 27203.953 | T18: =S18+N18+K18 -> 30788.256 | U18: =MIN(T18,MAX(0,Q18-R18)) -> 813.10465 | V18: =MAX(0,Q18-R18-U18) -> 0 | W18: =IF(B18=策略字典!$A$3,MIN(L18+H18,CEILING(V18/(F18*(1-参数设置!$B$23)),G18)),0) -> 0 | X18: =W18*F18 -> 0 | Y18: =X18*参数设置!$B$23 -> 0 | Z18: =X18-Y18 -> 0 | AA18: =MAX(0,V18-Z18) -> 0 | AB18: =MAX(0,Z18-V18) -> 0 | AC18: =T18-U18+AB18 -> 29975.151 | AD18: =MAX(0,L18+H18-W18) -> 30000 | AE18: =AD18*F18 -> 300000 | AF18: =SUM($C$7:C18)-SUM($O$7:O18) -> 280800 | AG18: =AF18/D18 -> 326511.63 | AH18: =AE18+AC18 -> 329975.15 | AI18: =AH18-AG18-SUM($AA$7:AA18) -> 3463.5233 | AJ18: =R18+U18+MIN(Z18,V18)+AA18-Q18 -> 0
A19: =EDATE(DATE(YEAR(参数设置!$B$4),MONTH(参数设置!$B$4),1),ROW()-7) -> 46600 | B19: 策略二：新贷偿还旧贷 | C19: =IF(AND(ROW()-6<=参数设置!$B$6,OR(B19=策略字典!$A$1,B19=策略字典!$A$2)),参数设置!$B$5,0) -> 23400 | D19: =参数设置!$B$7 -> 0.86 | E19: =IF(B19=策略字典!$A$1,C19/D19,0) -> 0 | F19: =参数设置!$B$18 -> 10 | G19: =参数设置!$B$19 -> 500 | H19: =IF(E19=0,0,FLOOR(E19/(F19*(1+参数设置!$B$22)),G19)) -> 0 | I19: =H19*F19 -> 0 | J19: =I19*参数设置!$B$22 -> 0 | K19: =MAX(0,E19-I19-J19) -> 0 | L19: =IF(ROW()=7,0,AD18) -> 30000 | M19: =(L19+H19)*参数设置!$B$20 -> 1500 | N19: =M18 -> 1500 | O19: =SUMIFS(贷款明细!$I$4:$I$435,贷款明细!$G$4:$G$435,">="&A19,贷款明细!$G$4:$G$435,"<"&EDATE(A19,1)) -> 23400 | P19: =SUMIFS(贷款明细!$J$4:$J$435,贷款明细!$G$4:$G$435,">="&A19,贷款明细!$G$4:$G$435,"<"&EDATE(A19,1)) -> 795.85 | Q19: =(O19+P19)/D19 -> 28134.709 | R19: =IF(B19=策略字典!$A$2,MIN(C19,O19)/D19,0) -> 27209.302 | S19: =IF(ROW()=7,0,AC18) -> 29975.151 | T19: =S19+N19+K19 -> 31475.151 | U19: =MIN(T19,MAX(0,Q19-R19)) -> 925.40698 | V19: =MAX(0,Q19-R19-U19) -> 0 | W19: =IF(B19=策略字典!$A$3,MIN(L19+H19,CEILING(V19/(F19*(1-参数设置!$B$23)),G19)),0) -> 0 | X19: =W19*F19 -> 0 | Y19: =X19*参数设置!$B$23 -> 0 | Z19: =X19-Y19 -> 0 | AA19: =MAX(0,V19-Z19) -> 0 | AB19: =MAX(0,Z19-V19) -> 0 | AC19: =T19-U19+AB19 -> 30549.744 | AD19: =MAX(0,L19+H19-W19) -> 30000 | AE19: =AD19*F19 -> 300000 | AF19: =SUM($C$7:C19)-SUM($O$7:O19) -> 280800 | AG19: =AF19/D19 -> 326511.63 | AH19: =AE19+AC19 -> 330549.74 | AI19: =AH19-AG19-SUM($AA$7:AA19) -> 4038.1163 | AJ19: =R19+U19+MIN(Z19,V19)+AA19-Q19 -> 0
... A54: =EDATE(DATE(YEAR(参数设置!$B$4),MONTH(参数设置!$B$4),1),ROW()-7) -> 47665 | B54: 期后：内部池优先+外部池 | C54: =IF(AND(ROW()-6<=参数设置!$B$6,OR(B54=策略字典!$A$1,B54=策略字典!$A$2)),参数设置!$B$5,0) -> 0 | D54: =参数设置!$B$7 -> 0.86 | E54: =IF(B54=策略字典!$A$1,C54/D54,0) -> 0 | F54: =参数设置!$B$18 -> 10 | G54: =参数设置!$B$19 -> 500 | H54: =IF(E54=0,0,FLOOR(E54/(F54*(1+参数设置!$B$22)),G54)) -> 0 | I54: =H54*F54 -> 0 | J54: =I54*参数设置!$B$22 -> 0 | K54: =MAX(0,E54-I54-J54) -> 0 | L54: =IF(ROW()=7,0,AD53) -> 1500 | M54: =(L54+H54)*参数设置!$B$20 -> 75 | N54: =M53 -> 75 | O54: =SUMIFS(贷款明细!$I$4:$I$435,贷款明细!$G$4:$G$435,">="&A54,贷款明细!$G$4:$G$435,"<"&EDATE(A54,1)) -> 0 | P54: =SUMIFS(贷款明细!$J$4:$J$435,贷款明细!$G$4:$G$435,">="&A54,贷款明细!$G$4:$G$435,"<"&EDATE(A54,1)) -> 0 | Q54: =(O54+P54)/D54 -> 0 | R54: =IF(B54=策略字典!$A$2,MIN(C54,O54)/D54,0) -> 0 | S54: =IF(ROW()=7,0,AC53) -> 2694.9535 | T54: =S54+N54+K54 -> 2769.9535 | U54: =MIN(T54,MAX(0,Q54-R54)) -> 0 | V54: =MAX(0,Q54-R54-U54) -> 0 | W54: =IF(B54=策略字典!$A$3,MIN(L54+H54,CEILING(V54/(F54*(1-参数设置!$B$23)),G54)),0) -> 0 | X54: =W54*F54 -> 0 | Y54: =X54*参数设置!$B$23 -> 0 | Z54: =X54-Y54 -> 0 | AA54: =MAX(0,V54-Z54) -> 0 | AB54: =MAX(0,Z54-V54) -> 0 | AC54: =T54-U54+AB54 -> 2769.9535 | AD54: =MAX(0,L54+H54-W54) -> 1500 | AE54: =AD54*F54 -> 15000 | AF54: =SUM($C$7:C54)-SUM($O$7:O54) -> 0 | AG54: =AF54/D54 -> 0 | AH54: =AE54+AC54 -> 17769.953 | AI54: =AH54-AG54-SUM($AA$7:AA54) -> 17769.953 | AJ54: =R54+U54+MIN(Z54,V54)+AA54-Q54 -> 0

Sheet 贷款明细
A1: 贷款明细（逐笔Actual/360计息）
A3: 贷款批次 | B3: 策略月份 | C3: 放款日 | D3: 贷款本金（人民币） | E3: 期数 | F3: 本期起始日 | G3: 本期还款日 | H3: 计息天数 | I3: 当期本金（人民币） | J3: 当期利息（人民币） | K3: 当期还款（人民币） | L3: 本金到期日 | M3: 是否启用
A4: 1 | B4: 1 | C4: =EDATE(参数设置!$B$4,A4-1) -> 46244 | D4: =IF(AND(A4<=参数设置!$B$6,OR(INDEX(月度资金流!$B$7:$B$42,A4)=策略字典!$A$1,INDEX(月度资金流!$B$7:$B$42,A4)=策略字典!$A$2)),参数设置!$B$5,0) -> 23400 | E4: 1 | F4: =IF(E4=1,C4,G3) -> 46244 | G4: =IF(E4<参数设置!$B$13,DATE(YEAR(EDATE(C4,E4+1)),MONTH(EDATE(C4,E4+1)),参数设置!$B$14),EDATE(C4,参数设置!$B$13)) -> 46300 | H4: =G4-F4 -> 56 | I4: =IF(E4=参数设置!$B$13,D4,0) -> 0 | J4: =IF(M4=1,ROUND(D4*参数设置!$B$11*H4/参数设置!$B$12,参数设置!$B$15),0) -> 120.12 | K4: =I4+J4 -> 120.12 | L4: =EDATE(C4,参数设置!$B$13) -> 46609 | M4: =--(D4>0) -> 1
A5: 1 | B5: 1 | C5: =EDATE(参数设置!$B$4,A5-1) -> 46244 | D5: =IF(AND(A5<=参数设置!$B$6,OR(INDEX(月度资金流!$B$7:$B$42,A5)=策略字典!$A$1,INDEX(月度资金流!$B$7:$B$42,A5)=策略字典!$A$2)),参数设置!$B$5,0) -> 23400 | E5: 2 | F5: =IF(E5=1,C5,G4) -> 46300 | G5: =IF(E5<参数设置!$B$13,DATE(YEAR(EDATE(C5,E5+1)),MONTH(EDATE(C5,E5+1)),参数设置!$B$14),EDATE(C5,参数设置!$B$13)) -> 46331 | H5: =G5-F5 -> 31 | I5: =IF(E5=参数设置!$B$13,D5,0) -> 0 | J5: =IF(M5=1,ROUND(D5*参数设置!$B$11*H5/参数设置!$B$12,参数设置!$B$15),0) -> 66.5 | K5: =I5+J5 -> 66.5 | L5: =EDATE(C5,参数设置!$B$13) -> 46609 | M5: =--(D5>0) -> 1
A6: 1 | B6: 1 | C6: =EDATE(参数设置!$B$4,A6-1) -> 46244 | D6: =IF(AND(A6<=参数设置!$B$6,OR(INDEX(月度资金流!$B$7:$B$42,A6)=策略字典!$A$1,INDEX(月度资金流!$B$7:$B$42,A6)=策略字典!$A$2)),参数设置!$B$5,0) -> 23400 | E6: 3 | F6: =IF(E6=1,C6,G5) -> 46331 | G6: =IF(E6<参数设置!$B$13,DATE(YEAR(EDATE(C6,E6+1)),MONTH(EDATE(C6,E6+1)),参数设置!$B$14),EDATE(C6,参数设置!$B$13)) -> 46361 | H6: =G6-F6 -> 30 | I6: =IF(E6=参数设置!$B$13,D6,0) -> 0 | J6: =IF(M6=1,ROUND(D6*参数设置!$B$11*H6/参数设置!$B$12,参数设置!$B$15),0) -> 64.35 | K6: =I6+J6 -> 64.35 | L6: =EDATE(C6,参数设置!$B$13) -> 46609 | M6: =--(D6>0) -> 1
A7: 1 | B7: 1 | C7: =EDATE(参数设置!$B$4,A7-1) -> 46244 | D7: =IF(AND(A7<=参数设置!$B$6,OR(INDEX(月度资金流!$B$7:$B$42,A7)=策略字典!$A$1,INDEX(月度资金流!$B$7:$B$42,A7)=策略字典!$A$2)),参数设置!$B$5,0) -> 23400 | E7: 4 | F7: =IF(E7=1,C7,G6) -> 46361 | G7: =IF(E7<参数设置!$B$13,DATE(YEAR(EDATE(C7,E7+1)),MONTH(EDATE(C7,E7+1)),参数设置!$B$14),EDATE(C7,参数设置!$B$13)) -> 46392 | H7: =G7-F7 -> 31 | I7: =IF(E7=参数设置!$B$13,D7,0) -> 0 | J7: =IF(M7=1,ROUND(D7*参数设置!$B$11*H7/参数设置!$B$12,参数设置!$B$15),0) -> 66.5 | K7: =I7+J7 -> 66.5 | L7: =EDATE(C7,参数设置!$B$13) -> 46609 | M7: =--(D7>0) -> 1
A8: 1 | B8: 1 | C8: =EDATE(参数设置!$B$4,A8-1) -> 46244 | D8: =IF(AND(A8<=参数设置!$B$6,OR(INDEX(月度资金流!$B$7:$B$42,A8)=策略字典!$A$1,INDEX(月度资金流!$B$7:$B$42,A8)=策略字典!$A$2)),参数设置!$B$5,0) -> 23400 | E8: 5 | F8: =IF(E8=1,C8,G7) -> 46392 | G8: =IF(E8<参数设置!$B$13,DATE(YEAR(EDATE(C8,E8+1)),MONTH(EDATE(C8,E8+1)),参数设置!$B$14),EDATE(C8,参数设置!$B$13)) -> 46423 | H8: =G8-F8 -> 31 | I8: =IF(E8=参数设置!$B$13,D8,0) -> 0 | J8: =IF(M8=1,ROUND(D8*参数设置!$B$11*H8/参数设置!$B$12,参数设置!$B$15),0) -> 66.5 | K8: =I8+J8 -> 66.5 | L8: =EDATE(C8,参数设置!$B$13) -> 46609 | M8: =--(D8>0) -> 1
A9: 1 | B9: 1 | C9: =EDATE(参数设置!$B$4,A9-1) -> 46244 | D9: =IF(AND(A9<=参数设置!$B$6,OR(INDEX(月度资金流!$B$7:$B$42,A9)=策略字典!$A$1,INDEX(月度资金流!$B$7:$B$42,A9)=策略字典!$A$2)),参数设置!$B$5,0) -> 23400 | E9: 6 | F9: =IF(E9=1,C9,G8) -> 46423 | G9: =IF(E9<参数设置!$B$13,DATE(YEAR(EDATE(C9,E9+1)),MONTH(EDATE(C9,E9+1)),参数设置!$B$14),EDATE(C9,参数设置!$B$13)) -> 46451 | H9: =G9-F9 -> 28 | I9: =IF(E9=参数设置!$B$13,D9,0) -> 0 | J9: =IF(M9=1,ROUND(D9*参数设置!$B$11*H9/参数设置!$B$12,参数设置!$B$15),0) -> 60.06 | K9: =I9+J9 -> 60.06 | L9: =EDATE(C9,参数设置!$B$13) -> 46609 | M9: =--(D9>0) -> 1
A10: 1 | B10: 1 | C10: =EDATE(参数设置!$B$4,A10-1) -> 46244 | D10: =IF(AND(A10<=参数设置!$B$6,OR(INDEX(月度资金流!$B$7:$B$42,A10)=策略字典!$A$1,INDEX(月度资金流!$B$7:$B$42,A10)=策略字典!$A$2)),参数设置!$B$5,0) -> 23400 | E10: 7 | F10: =IF(E10=1,C10,G9) -> 46451 | G10: =IF(E10<参数设置!$B$13,DATE(YEAR(EDATE(C10,E10+1)),MONTH(EDATE(C10,E10+1)),参数设置!$B$14),EDATE(C10,参数设置!$B$13)) -> 46482 | H10: =G10-F10 -> 31 | I10: =IF(E10=参数设置!$B$13,D10,0) -> 0 | J10: =IF(M10=1,ROUND(D10*参数设置!$B$11*H10/参数设置!$B$12,参数设置!$B$15),0) -> 66.5 | K10: =I10+J10 -> 66.5 | L10: =EDATE(C10,参数设置!$B$13) -> 46609 | M10: =--(D10>0) -> 1
A11: 1 | B11: 1 | C11: =EDATE(参数设置!$B$4,A11-1) -> 46244 | D11: =IF(AND(A11<=参数设置!$B$6,OR(INDEX(月度资金流!$B$7:$B$42,A11)=策略字典!$A$1,INDEX(月度资金流!$B$7:$B$42,A11)=策略字典!$A$2)),参数设置!$B$5,0) -> 23400 | E11: 8 | F11: =IF(E11=1,C11,G10) -> 46482 | G11: =IF(E11<参数设置!$B$13,DATE(YEAR(EDATE(C11,E11+1)),MONTH(EDATE(C11,E11+1)),参数设置!$B$14),EDATE(C11,参数设置!$B$13)) -> 46512 | H11: =G11-F11 -> 30 | I11: =IF(E11=参数设置!$B$13,D11,0) -> 0 | J11: =IF(M11=1,ROUND(D11*参数设置!$B$11*H11/参数设置!$B$12,参数设置!$B$15),0) -> 64.35 | K11: =I11+J11 -> 64.35 | L11: =EDATE(C11,参数设置!$B$13) -> 46609 | M11: =--(D11>0) -> 1
A12: 1 | B12: 1 | C12: =EDATE(参数设置!$B$4,A12-1) -> 46244 | D12: =IF(AND(A12<=参数设置!$B$6,OR(INDEX(月度资金流!$B$7:$B$42,A12)=策略字典!$A$1,INDEX(月度资金流!$B$7:$B$42,A12)=策略字典!$A$2)),参数设置!$B$5,0) -> 23400 | E12: 9 | F12: =IF(E12=1,C12,G11) -> 46512 | G12: =IF(E12<参数设置!$B$13,DATE(YEAR(EDATE(C12,E12+1)),MONTH(EDATE(C12,E12+1)),参数设置!$B$14),EDATE(C12,参数设置!$B$13)) -> 46543 | H12: =G12-F12 -> 31 | I12: =IF(E12=参数设置!$B$13,D12,0) -> 0 | J12: =IF(M12=1,ROUND(D12*参数设置!$B$11*H12/参数设置!$B$12,参数设置!$B$15),0) -> 66.5 | K12: =I12+J12 -> 66.5 | L12: =EDATE(C12,参数设置!$B$13) -> 46609 | M12: =--(D12>0) -> 1
A13: 1 | B13: 1 | C13: =EDATE(参数设置!$B$4,A13-1) -> 46244 | D13: =IF(AND(A13<=参数设置!$B$6,OR(INDEX(月度资金流!$B$7:$B$42,A13)=策略字典!$A$1,INDEX(月度资金流!$B$7:$B$42,A13)=策略字典!$A$2)),参数设置!$B$5,0) -> 23400 | E13: 10 | F13: =IF(E13=1,C13,G12) -> 46543 | G13: =IF(E13<参数设置!$B$13,DATE(YEAR(EDATE(C13,E13+1)),MONTH(EDATE(C13,E13+1)),参数设置!$B$14),EDATE(C13,参数设置!$B$13)) -> 46573 | H13: =G13-F13 -> 30 | I13: =IF(E13=参数设置!$B$13,D13,0) -> 0 | J13: =IF(M13=1,ROUND(D13*参数设置!$B$11*H13/参数设置!$B$12,参数设置!$B$15),0) -> 64.35 | K13: =I13+J13 -> 64.35 | L13: =EDATE(C13,参数设置!$B$13) -> 46609 | M13: =--(D13>0) -> 1
A14: 1 | B14: 1 | C14: =EDATE(参数设置!$B$4,A14-1) -> 46244 | D14: =IF(AND(A14<=参数设置!$B$6,OR(INDEX(月度资金流!$B$7:$B$42,A14)=策略字典!$A$1,INDEX(月度资金流!$B$7:$B$42,A14)=策略字典!$A$2)),参数设置!$B$5,0) -> 23400 | E14: 11 | F14: =IF(E14=1,C14,G13) -> 46573 | G14: =IF(E14<参数设置!$B$13,DATE(YEAR(EDATE(C14,E14+1)),MONTH(EDATE(C14,E14+1)),参数设置!$B$14),EDATE(C14,参数设置!$B$13)) -> 46604 | H14: =G14-F14 -> 31 | I14: =IF(E14=参数设置!$B$13,D14,0) -> 0 | J14: =IF(M14=1,ROUND(D14*参数设置!$B$11*H14/参数设置!$B$12,参数设置!$B$15),0) -> 66.5 | K14: =I14+J14 -> 66.5 | L14: =EDATE(C14,参数设置!$B$13) -> 46609 | M14: =--(D14>0) -> 1
A15: 1 | B15: 1 | C15: =EDATE(参数设置!$B$4,A15-1) -> 46244 | D15: =IF(AND(A15<=参数设置!$B$6,OR(INDEX(月度资金流!$B$7:$B$42,A15)=策略字典!$A$1,INDEX(月度资金流!$B$7:$B$42,A15)=策略字典!$A$2)),参数设置!$B$5,0) -> 23400 | E15: 12 | F15: =IF(E15=1,C15,G14) -> 46604 | G15: =IF(E15<参数设置!$B$13,DATE(YEAR(EDATE(C15,E15+1)),MONTH(EDATE(C15,E15+1)),参数设置!$B$14),EDATE(C15,参数设置!$B$13)) -> 46609 | H15: =G15-F15 -> 5 | I15: =IF(E15=参数设置!$B$13,D15,0) -> 23400 | J15: =IF(M15=1,ROUND(D15*参数设置!$B$11*H15/参数设置!$B$12,参数设置!$B$15),0) -> 10.73 | K15: =I15+J15 -> 23410.73 | L15: =EDATE(C15,参数设置!$B$13) -> 46609 | M15: =--(D15>0) -> 1
... A435: 36 | B435: 36 | C435: =EDATE(参数设置!$B$4,A435-1) -> 47309 | D435: =IF(AND(A435<=参数设置!$B$6,OR(INDEX(月度资金流!$B$7:$B$42,A435)=策略字典!$A$1,INDEX(月度资金流!$B$7:$B$42,A435)=策略字典!$A$2)),参数设置!$B$5,0) -> 0 | E435: 12 | F435: =IF(E435=1,C435,G434) -> 47669 | G435: =IF(E435<参数设置!$B$13,DATE(YEAR(EDATE(C435,E435+1)),MONTH(EDATE(C435,E435+1)),参数设置!$B$14),EDATE(C435,参数设置!$B$13)) -> 47674 | H435: =G435-F435 -> 5 | I435: =IF(E435=参数设置!$B$13,D435,0) -> 0 | J435: =IF(M435=1,ROUND(D435*参数设置!$B$11*H435/参数设置!$B$12,参数设置!$B$15),0) -> 0 | K435: =I435+J435 -> 0 | L435: =EDATE(C435,参数设置!$B$13) -> 47674 | M435: =--(D435>0) -> 0

Sheet 实际执行追踪
A1: 实际执行追踪（黄色蓝字为每月实际输入）
A6: 月份 | B6: 当月策略 | C6: 新增贷款（人民币） | D6: 汇率 | E6: 可用港币 | F6: 单位价格 | G6: 每手股数 | H6: 买入股数 | I6: 基金买入金额 | J6: 申购费 | K6: 买入找零 | L6: 期初持仓 | M6: 当月应计分红 | N6: 实际每股分红（港币） | O6: 应还本金（人民币） | P6: 应还利息（人民币） | Q6: 总还款（港币） | R6: 新贷款抵还 | S6: 内部池期初 | T6: 分红及找零后内部池 | U6: 内部池用于还款 | V6: 还款缺口 | W6: 卖出股数 | X6: 卖出毛额 | Y6: 赎回费 | Z6: 卖出净额 | AA6: 外部资金池投入 | AB6: 卖出超额入内部池 | AC6: 内部现金池期末 | AD6: 期末持仓 | AE6: 期末基金市值 | AF6: 期末未偿贷款（人民币） | AG6: 负债折港币 | AH6: 基金+内部池 | AI6: 策略净资产 | AJ6: 资金来源校验
A7: =EDATE(DATE(YEAR(参数设置!$B$4),MONTH(参数设置!$B$4),1),ROW()-7) -> 46235 | B7: 策略一：消费贷款+买基金 | C7: 23400 | D7: 0.86 | E7: =IF(B7=策略字典!$A$1,C7/D7,0) -> 27209.302 | F7: 10 | G7: 500 | H7: =IF(E7=0,0,FLOOR((E7-J7)/F7,G7)) -> 2500 | I7: =H7*F7 -> 25000 | J7: 0 | K7: =MAX(0,E7-I7-J7) -> 2209.3023 | L7: =IF(ROW()=7,0,AD6) -> 0 | M7: =0 -> 0 | N7: 0 | O7: =SUMIFS(实际贷款明细!$I$4:$I$435,实际贷款明细!$G$4:$G$435,">="&A7,实际贷款明细!$G$4:$G$435,"<"&EDATE(A7,1)) -> 0 | P7: =SUMIFS(实际贷款明细!$J$4:$J$435,实际贷款明细!$G$4:$G$435,">="&A7,实际贷款明细!$G$4:$G$435,"<"&EDATE(A7,1)) -> 0 | Q7: =(O7+P7)/D7 -> 0 | R7: =IF(B7=策略字典!$A$2,MIN(C7,O7)/D7,0) -> 0 | S7: =IF(ROW()=7,0,AC6) -> 0 | T7: =S7+L7*N7+K7 -> 2209.3023 | U7: =MIN(T7,MAX(0,Q7-R7)) -> 0 | V7: =MAX(0,Q7-R7-U7) -> 0 | W7: =IF(B7=策略字典!$A$3,MIN(L7+H7,CEILING(V7/(F7*(1-参数设置!$B$23)),G7)),0) -> 0 | X7: =W7*F7 -> 0 | Y7: =X7*参数设置!$B$23 -> 0 | Z7: =X7-Y7 -> 0 | AA7: =MAX(0,V7-Z7) -> 0 | AB7: =MAX(0,Z7-V7) -> 0 | AC7: =T7-U7+AB7 -> 2209.3023 | AD7: =MAX(0,L7+H7-W7) -> 2500 | AE7: =AD7*F7 -> 25000 | AF7: =SUM($C$7:C7)-SUM($O$7:O7) -> 23400 | AG7: =AF7/D7 -> 27209.302 | AH7: =AE7+AC7 -> 27209.302 | AI7: =AH7-AG7-SUM($AA$7:AA7) -> 0 | AJ7: =R7+U7+MIN(Z7,V7)+AA7-Q7 -> 0
A8: =EDATE(DATE(YEAR(参数设置!$B$4),MONTH(参数设置!$B$4),1),ROW()-7) -> 46266 | B8: 策略一：消费贷款+买基金 | C8: 23400 | D8: 0.86 | E8: =IF(B8=策略字典!$A$1,C8/D8,0) -> 27209.302 | F8: 10 | G8: 500 | H8: =IF(E8=0,0,FLOOR((E8-J8)/F8,G8)) -> 2500 | I8: =H8*F8 -> 25000 | J8: 0 | K8: =MAX(0,E8-I8-J8) -> 2209.3023 | L8: =IF(ROW()=7,0,AD7) -> 2500 | M8: =0 -> 0 | N8: 0.05 | O8: =SUMIFS(实际贷款明细!$I$4:$I$435,实际贷款明细!$G$4:$G$435,">="&A8,实际贷款明细!$G$4:$G$435,"<"&EDATE(A8,1)) -> 0 | P8: =SUMIFS(实际贷款明细!$J$4:$J$435,实际贷款明细!$G$4:$G$435,">="&A8,实际贷款明细!$G$4:$G$435,"<"&EDATE(A8,1)) -> 0 | Q8: =(O8+P8)/D8 -> 0 | R8: =IF(B8=策略字典!$A$2,MIN(C8,O8)/D8,0) -> 0 | S8: =IF(ROW()=7,0,AC7) -> 2209.3023 | T8: =S8+L8*N8+K8 -> 4543.6047 | U8: =MIN(T8,MAX(0,Q8-R8)) -> 0 | V8: =MAX(0,Q8-R8-U8) -> 0 | W8: =IF(B8=策略字典!$A$3,MIN(L8+H8,CEILING(V8/(F8*(1-参数设置!$B$23)),G8)),0) -> 0 | X8: =W8*F8 -> 0 | Y8: =X8*参数设置!$B$23 -> 0 | Z8: =X8-Y8 -> 0 | AA8: =MAX(0,V8-Z8) -> 0 | AB8: =MAX(0,Z8-V8) -> 0 | AC8: =T8-U8+AB8 -> 4543.6047 | AD8: =MAX(0,L8+H8-W8) -> 5000 | AE8: =AD8*F8 -> 50000 | AF8: =SUM($C$7:C8)-SUM($O$7:O8) -> 46800 | AG8: =AF8/D8 -> 54418.605 | AH8: =AE8+AC8 -> 54543.605 | AI8: =AH8-AG8-SUM($AA$7:AA8) -> 125 | AJ8: =R8+U8+MIN(Z8,V8)+AA8-Q8 -> 0
A9: =EDATE(DATE(YEAR(参数设置!$B$4),MONTH(参数设置!$B$4),1),ROW()-7) -> 46296 | B9: 策略一：消费贷款+买基金 | C9: 23400 | D9: 0.86 | E9: =IF(B9=策略字典!$A$1,C9/D9,0) -> 27209.302 | F9: 10 | G9: 500 | H9: =IF(E9=0,0,FLOOR((E9-J9)/F9,G9)) -> 2500 | I9: =H9*F9 -> 25000 | J9: 0 | K9: =MAX(0,E9-I9-J9) -> 2209.3023 | L9: =IF(ROW()=7,0,AD8) -> 5000 | M9: =0 -> 0 | N9: 0.05 | O9: =SUMIFS(实际贷款明细!$I$4:$I$435,实际贷款明细!$G$4:$G$435,">="&A9,实际贷款明细!$G$4:$G$435,"<"&EDATE(A9,1)) -> 0 | P9: =SUMIFS(实际贷款明细!$J$4:$J$435,实际贷款明细!$G$4:$G$435,">="&A9,实际贷款明细!$G$4:$G$435,"<"&EDATE(A9,1)) -> 120.12 | Q9: =(O9+P9)/D9 -> 139.67442 | R9: =IF(B9=策略字典!$A$2,MIN(C9,O9)/D9,0) -> 0 | S9: =IF(ROW()=7,0,AC8) -> 4543.6047 | T9: =S9+L9*N9+K9 -> 7002.907 | U9: =MIN(T9,MAX(0,Q9-R9)) -> 139.67442 | V9: =MAX(0,Q9-R9-U9) -> 0 | W9: =IF(B9=策略字典!$A$3,MIN(L9+H9,CEILING(V9/(F9*(1-参数设置!$B$23)),G9)),0) -> 0 | X9: =W9*F9 -> 0 | Y9: =X9*参数设置!$B$23 -> 0 | Z9: =X9-Y9 -> 0 | AA9: =MAX(0,V9-Z9) -> 0 | AB9: =MAX(0,Z9-V9) -> 0 | AC9: =T9-U9+AB9 -> 6863.2326 | AD9: =MAX(0,L9+H9-W9) -> 7500 | AE9: =AD9*F9 -> 75000 | AF9: =SUM($C$7:C9)-SUM($O$7:O9) -> 70200 | AG9: =AF9/D9 -> 81627.907 | AH9: =AE9+AC9 -> 81863.233 | AI9: =AH9-AG9-SUM($AA$7:AA9) -> 235.32558 | AJ9: =R9+U9+MIN(Z9,V9)+AA9-Q9 -> 0
A10: =EDATE(DATE(YEAR(参数设置!$B$4),MONTH(参数设置!$B$4),1),ROW()-7) -> 46327 | B10: 策略一：消费贷款+买基金 | C10: 23400 | D10: 0.86 | E10: =IF(B10=策略字典!$A$1,C10/D10,0) -> 27209.302 | F10: 10 | G10: 500 | H10: =IF(E10=0,0,FLOOR((E10-J10)/F10,G10)) -> 2500 | I10: =H10*F10 -> 25000 | J10: 0 | K10: =MAX(0,E10-I10-J10) -> 2209.3023 | L10: =IF(ROW()=7,0,AD9) -> 7500 | M10: =0 -> 0 | N10: 0.05 | O10: =SUMIFS(实际贷款明细!$I$4:$I$435,实际贷款明细!$G$4:$G$435,">="&A10,实际贷款明细!$G$4:$G$435,"<"&EDATE(A10,1)) -> 0 | P10: =SUMIFS(实际贷款明细!$J$4:$J$435,实际贷款明细!$G$4:$G$435,">="&A10,实际贷款明细!$G$4:$G$435,"<"&EDATE(A10,1)) -> 186.62 | Q10: =(O10+P10)/D10 -> 217 | R10: =IF(B10=策略字典!$A$2,MIN(C10,O10)/D10,0) -> 0 | S10: =IF(ROW()=7,0,AC9) -> 6863.2326 | T10: =S10+L10*N10+K10 -> 9447.5349 | U10: =MIN(T10,MAX(0,Q10-R10)) -> 217 | V10: =MAX(0,Q10-R10-U10) -> 0 | W10: =IF(B10=策略字典!$A$3,MIN(L10+H10,CEILING(V10/(F10*(1-参数设置!$B$23)),G10)),0) -> 0 | X10: =W10*F10 -> 0 | Y10: =X10*参数设置!$B$23 -> 0 | Z10: =X10-Y10 -> 0 | AA10: =MAX(0,V10-Z10) -> 0 | AB10: =MAX(0,Z10-V10) -> 0 | AC10: =T10-U10+AB10 -> 9230.5349 | AD10: =MAX(0,L10+H10-W10) -> 10000 | AE10: =AD10*F10 -> 100000 | AF10: =SUM($C$7:C10)-SUM($O$7:O10) -> 93600 | AG10: =AF10/D10 -> 108837.21 | AH10: =AE10+AC10 -> 109230.53 | AI10: =AH10-AG10-SUM($AA$7:AA10) -> 393.32558 | AJ10: =R10+U10+MIN(Z10,V10)+AA10-Q10 -> 0
A11: =EDATE(DATE(YEAR(参数设置!$B$4),MONTH(参数设置!$B$4),1),ROW()-7) -> 46357 | B11: 策略一：消费贷款+买基金 | C11: 23400 | D11: 0.86 | E11: =IF(B11=策略字典!$A$1,C11/D11,0) -> 27209.302 | F11: 10 | G11: 500 | H11: =IF(E11=0,0,FLOOR((E11-J11)/F11,G11)) -> 2500 | I11: =H11*F11 -> 25000 | J11: 0 | K11: =MAX(0,E11-I11-J11) -> 2209.3023 | L11: =IF(ROW()=7,0,AD10) -> 10000 | M11: =0 -> 0 | N11: 0.05 | O11: =SUMIFS(实际贷款明细!$I$4:$I$435,实际贷款明细!$G$4:$G$435,">="&A11,实际贷款明细!$G$4:$G$435,"<"&EDATE(A11,1)) -> 0 | P11: =SUMIFS(实际贷款明细!$J$4:$J$435,实际贷款明细!$G$4:$G$435,">="&A11,实际贷款明细!$G$4:$G$435,"<"&EDATE(A11,1)) -> 248.82 | Q11: =(O11+P11)/D11 -> 289.32558 | R11: =IF(B11=策略字典!$A$2,MIN(C11,O11)/D11,0) -> 0 | S11: =IF(ROW()=7,0,AC10) -> 9230.5349 | T11: =S11+L11*N11+K11 -> 11939.837 | U11: =MIN(T11,MAX(0,Q11-R11)) -> 289.32558 | V11: =MAX(0,Q11-R11-U11) -> 0 | W11: =IF(B11=策略字典!$A$3,MIN(L11+H11,CEILING(V11/(F11*(1-参数设置!$B$23)),G11)),0) -> 0 | X11: =W11*F11 -> 0 | Y11: =X11*参数设置!$B$23 -> 0 | Z11: =X11-Y11 -> 0 | AA11: =MAX(0,V11-Z11) -> 0 | AB11: =MAX(0,Z11-V11) -> 0 | AC11: =T11-U11+AB11 -> 11650.512 | AD11: =MAX(0,L11+H11-W11) -> 12500 | AE11: =AD11*F11 -> 125000 | AF11: =SUM($C$7:C11)-SUM($O$7:O11) -> 117000 | AG11: =AF11/D11 -> 136046.51 | AH11: =AE11+AC11 -> 136650.51 | AI11: =AH11-AG11-SUM($AA$7:AA11) -> 604 | AJ11: =R11+U11+MIN(Z11,V11)+AA11-Q11 -> 0
A12: =EDATE(DATE(YEAR(参数设置!$B$4),MONTH(参数设置!$B$4),1),ROW()-7) -> 46388 | B12: 策略一：消费贷款+买基金 | C12: 23400 | D12: 0.86 | E12: =IF(B12=策略字典!$A$1,C12/D12,0) -> 27209.302 | F12: 10 | G12: 500 | H12: =IF(E12=0,0,FLOOR((E12-J12)/F12,G12)) -> 2500 | I12: =H12*F12 -> 25000 | J12: 0 | K12: =MAX(0,E12-I12-J12) -> 2209.3023 | L12: =IF(ROW()=7,0,AD11) -> 12500 | M12: =0 -> 0 | N12: 0.05 | O12: =SUMIFS(实际贷款明细!$I$4:$I$435,实际贷款明细!$G$4:$G$435,">="&A12,实际贷款明细!$G$4:$G$435,"<"&EDATE(A12,1)) -> 0 | P12: =SUMIFS(实际贷款明细!$J$4:$J$435,实际贷款明细!$G$4:$G$435,">="&A12,实际贷款明细!$G$4:$G$435,"<"&EDATE(A12,1)) -> 319.62 | Q12: =(O12+P12)/D12 -> 371.65116 | R12: =IF(B12=策略字典!$A$2,MIN(C12,O12)/D12,0) -> 0 | S12: =IF(ROW()=7,0,AC11) -> 11650.512 | T12: =S12+L12*N12+K12 -> 14484.814 | U12: =MIN(T12,MAX(0,Q12-R12)) -> 371.65116 | V12: =MAX(0,Q12-R12-U12) -> 0 | W12: =IF(B12=策略字典!$A$3,MIN(L12+H12,CEILING(V12/(F12*(1-参数设置!$B$23)),G12)),0) -> 0 | X12: =W12*F12 -> 0 | Y12: =X12*参数设置!$B$23 -> 0 | Z12: =X12-Y12 -> 0 | AA12: =MAX(0,V12-Z12) -> 0 | AB12: =MAX(0,Z12-V12) -> 0 | AC12: =T12-U12+AB12 -> 14113.163 | AD12: =MAX(0,L12+H12-W12) -> 15000 | AE12: =AD12*F12 -> 150000 | AF12: =SUM($C$7:C12)-SUM($O$7:O12) -> 140400 | AG12: =AF12/D12 -> 163255.81 | AH12: =AE12+AC12 -> 164113.16 | AI12: =AH12-AG12-SUM($AA$7:AA12) -> 857.34884 | AJ12: =R12+U12+MIN(Z12,V12)+AA12-Q12 -> 0
A13: =EDATE(DATE(YEAR(参数设置!$B$4),MONTH(参数设置!$B$4),1),ROW()-7) -> 46419 | B13: 策略一：消费贷款+买基金 | C13: 23400 | D13: 0.86 | E13: =IF(B13=策略字典!$A$1,C13/D13,0) -> 27209.302 | F13: 10 | G13: 500 | H13: =IF(E13=0,0,FLOOR((E13-J13)/F13,G13)) -> 2500 | I13: =H13*F13 -> 25000 | J13: 0 | K13: =MAX(0,E13-I13-J13) -> 2209.3023 | L13: =IF(ROW()=7,0,AD12) -> 15000 | M13: =0 -> 0 | N13: 0.05 | O13: =SUMIFS(实际贷款明细!$I$4:$I$435,实际贷款明细!$G$4:$G$435,">="&A13,实际贷款明细!$G$4:$G$435,"<"&EDATE(A13,1)) -> 0 | P13: =SUMIFS(实际贷款明细!$J$4:$J$435,实际贷款明细!$G$4:$G$435,">="&A13,实际贷款明细!$G$4:$G$435,"<"&EDATE(A13,1)) -> 388.27 | Q13: =(O13+P13)/D13 -> 451.47674 | R13: =IF(B13=策略字典!$A$2,MIN(C13,O13)/D13,0) -> 0 | S13: =IF(ROW()=7,0,AC12) -> 14113.163 | T13: =S13+L13*N13+K13 -> 17072.465 | U13: =MIN(T13,MAX(0,Q13-R13)) -> 451.47674 | V13: =MAX(0,Q13-R13-U13) -> 0 | W13: =IF(B13=策略字典!$A$3,MIN(L13+H13,CEILING(V13/(F13*(1-参数设置!$B$23)),G13)),0) -> 0 | X13: =W13*F13 -> 0 | Y13: =X13*参数设置!$B$23 -> 0 | Z13: =X13-Y13 -> 0 | AA13: =MAX(0,V13-Z13) -> 0 | AB13: =MAX(0,Z13-V13) -> 0 | AC13: =T13-U13+AB13 -> 16620.988 | AD13: =MAX(0,L13+H13-W13) -> 17500 | AE13: =AD13*F13 -> 175000 | AF13: =SUM($C$7:C13)-SUM($O$7:O13) -> 163800 | AG13: =AF13/D13 -> 190465.12 | AH13: =AE13+AC13 -> 191620.99 | AI13: =AH13-AG13-SUM($AA$7:AA13) -> 1155.8721 | AJ13: =R13+U13+MIN(Z13,V13)+AA13-Q13 -> 0
A14: =EDATE(DATE(YEAR(参数设置!$B$4),MONTH(参数设置!$B$4),1),ROW()-7) -> 46447 | B14: 策略一：消费贷款+买基金 | C14: 23400 | D14: 0.86 | E14: =IF(B14=策略字典!$A$1,C14/D14,0) -> 27209.302 | F14: 10 | G14: 500 | H14: =IF(E14=0,0,FLOOR((E14-J14)/F14,G14)) -> 2500 | I14: =H14*F14 -> 25000 | J14: 0 | K14: =MAX(0,E14-I14-J14) -> 2209.3023 | L14: =IF(ROW()=7,0,AD13) -> 17500 | M14: =0 -> 0 | N14: 0.05 | O14: =SUMIFS(实际贷款明细!$I$4:$I$435,实际贷款明细!$G$4:$G$435,">="&A14,实际贷款明细!$G$4:$G$435,"<"&EDATE(A14,1)) -> 0 | P14: =SUMIFS(实际贷款明细!$J$4:$J$435,实际贷款明细!$G$4:$G$435,">="&A14,实际贷款明细!$G$4:$G$435,"<"&EDATE(A14,1)) -> 416.13 | Q14: =(O14+P14)/D14 -> 483.87209 | R14: =IF(B14=策略字典!$A$2,MIN(C14,O14)/D14,0) -> 0 | S14: =IF(ROW()=7,0,AC13) -> 16620.988 | T14: =S14+L14*N14+K14 -> 19705.291 | U14: =MIN(T14,MAX(0,Q14-R14)) -> 483.87209 | V14: =MAX(0,Q14-R14-U14) -> 0 | W14: =IF(B14=策略字典!$A$3,MIN(L14+H14,CEILING(V14/(F14*(1-参数设置!$B$23)),G14)),0) -> 0 | X14: =W14*F14 -> 0 | Y14: =X14*参数设置!$B$23 -> 0 | Z14: =X14-Y14 -> 0 | AA14: =MAX(0,V14-Z14) -> 0 | AB14: =MAX(0,Z14-V14) -> 0 | AC14: =T14-U14+AB14 -> 19221.419 | AD14: =MAX(0,L14+H14-W14) -> 20000 | AE14: =AD14*F14 -> 200000 | AF14: =SUM($C$7:C14)-SUM($O$7:O14) -> 187200 | AG14: =AF14/D14 -> 217674.42 | AH14: =AE14+AC14 -> 219221.42 | AI14: =AH14-AG14-SUM($AA$7:AA14) -> 1547 | AJ14: =R14+U14+MIN(Z14,V14)+AA14-Q14 -> 0
A15: =EDATE(DATE(YEAR(参数设置!$B$4),MONTH(参数设置!$B$4),1),ROW()-7) -> 46478 | B15: 策略一：消费贷款+买基金 | C15: 23400 | D15: 0.86 | E15: =IF(B15=策略字典!$A$1,C15/D15,0) -> 27209.302 | F15: 10 | G15: 500 | H15: =IF(E15=0,0,FLOOR((E15-J15)/F15,G15)) -> 2500 | I15: =H15*F15 -> 25000 | J15: 0 | K15: =MAX(0,E15-I15-J15) -> 2209.3023 | L15: =IF(ROW()=7,0,AD14) -> 20000 | M15: =0 -> 0 | N15: 0.05 | O15: =SUMIFS(实际贷款明细!$I$4:$I$435,实际贷款明细!$G$4:$G$435,">="&A15,实际贷款明细!$G$4:$G$435,"<"&EDATE(A15,1)) -> 0 | P15: =SUMIFS(实际贷款明细!$J$4:$J$435,实际贷款明细!$G$4:$G$435,">="&A15,实际贷款明细!$G$4:$G$435,"<"&EDATE(A15,1)) -> 514.83 | Q15: =(O15+P15)/D15 -> 598.63953 | R15: =IF(B15=策略字典!$A$2,MIN(C15,O15)/D15,0) -> 0 | S15: =IF(ROW()=7,0,AC14) -> 19221.419 | T15: =S15+L15*N15+K15 -> 22430.721 | U15: =MIN(T15,MAX(0,Q15-R15)) -> 598.63953 | V15: =MAX(0,Q15-R15-U15) -> 0 | W15: =IF(B15=策略字典!$A$3,MIN(L15+H15,CEILING(V15/(F15*(1-参数设置!$B$23)),G15)),0) -> 0 | X15: =W15*F15 -> 0 | Y15: =X15*参数设置!$B$23 -> 0 | Z15: =X15-Y15 -> 0 | AA15: =MAX(0,V15-Z15) -> 0 | AB15: =MAX(0,Z15-V15) -> 0 | AC15: =T15-U15+AB15 -> 21832.081 | AD15: =MAX(0,L15+H15-W15) -> 22500 | AE15: =AD15*F15 -> 225000 | AF15: =SUM($C$7:C15)-SUM($O$7:O15) -> 210600 | AG15: =AF15/D15 -> 244883.72 | AH15: =AE15+AC15 -> 246832.08 | AI15: =AH15-AG15-SUM($AA$7:AA15) -> 1948.3605 | AJ15: =R15+U15+MIN(Z15,V15)+AA15-Q15 -> 0
A16: =EDATE(DATE(YEAR(参数设置!$B$4),MONTH(参数设置!$B$4),1),ROW()-7) -> 46508 | B16: 策略一：消费贷款+买基金 | C16: 23400 | D16: 0.86 | E16: =IF(B16=策略字典!$A$1,C16/D16,0) -> 27209.302 | F16: 10 | G16: 500 | H16: =IF(E16=0,0,FLOOR((E16-J16)/F16,G16)) -> 2500 | I16: =H16*F16 -> 25000 | J16: 0 | K16: =MAX(0,E16-I16-J16) -> 2209.3023 | L16: =IF(ROW()=7,0,AD15) -> 22500 | M16: =0 -> 0 | N16: 0.05 | O16: =SUMIFS(实际贷款明细!$I$4:$I$435,实际贷款明细!$G$4:$G$435,">="&A16,实际贷款明细!$G$4:$G$435,"<"&EDATE(A16,1)) -> 0 | P16: =SUMIFS(实际贷款明细!$J$4:$J$435,实际贷款明细!$G$4:$G$435,">="&A16,实际贷款明细!$G$4:$G$435,"<"&EDATE(A16,1)) -> 570.57 | Q16: =(O16+P16)/D16 -> 663.45349 | R16: =IF(B16=策略字典!$A$2,MIN(C16,O16)/D16,0) -> 0 | S16: =IF(ROW()=7,0,AC15) -> 21832.081 | T16: =S16+L16*N16+K16 -> 25166.384 | U16: =MIN(T16,MAX(0,Q16-R16)) -> 663.45349 | V16: =MAX(0,Q16-R16-U16) -> 0 | W16: =IF(B16=策略字典!$A$3,MIN(L16+H16,CEILING(V16/(F16*(1-参数设置!$B$23)),G16)),0) -> 0 | X16: =W16*F16 -> 0 | Y16: =X16*参数设置!$B$23 -> 0 | Z16: =X16-Y16 -> 0 | AA16: =MAX(0,V16-Z16) -> 0 | AB16: =MAX(0,Z16-V16) -> 0 | AC16: =T16-U16+AB16 -> 24502.93 | AD16: =MAX(0,L16+H16-W16) -> 25000 | AE16: =AD16*F16 -> 250000 | AF16: =SUM($C$7:C16)-SUM($O$7:O16) -> 234000 | AG16: =AF16/D16 -> 272093.02 | AH16: =AE16+AC16 -> 274502.93 | AI16: =AH16-AG16-SUM($AA$7:AA16) -> 2409.907 | AJ16: =R16+U16+MIN(Z16,V16)+AA16-Q16 -> 0
A17: =EDATE(DATE(YEAR(参数设置!$B$4),MONTH(参数设置!$B$4),1),ROW()-7) -> 46539 | B17: 策略一：消费贷款+买基金 | C17: 23400 | D17: 0.86 | E17: =IF(B17=策略字典!$A$1,C17/D17,0) -> 27209.302 | F17: 10 | G17: 500 | H17: =IF(E17=0,0,FLOOR((E17-J17)/F17,G17)) -> 2500 | I17: =H17*F17 -> 25000 | J17: 0 | K17: =MAX(0,E17-I17-J17) -> 2209.3023 | L17: =IF(ROW()=7,0,AD16) -> 25000 | M17: =0 -> 0 | N17: 0.05 | O17: =SUMIFS(实际贷款明细!$I$4:$I$435,实际贷款明细!$G$4:$G$435,">="&A17,实际贷款明细!$G$4:$G$435,"<"&EDATE(A17,1)) -> 0 | P17: =SUMIFS(实际贷款明细!$J$4:$J$435,实际贷款明细!$G$4:$G$435,">="&A17,实际贷款明细!$G$4:$G$435,"<"&EDATE(A17,1)) -> 652.12 | Q17: =(O17+P17)/D17 -> 758.27907 | R17: =IF(B17=策略字典!$A$2,MIN(C17,O17)/D17,0) -> 0 | S17: =IF(ROW()=7,0,AC16) -> 24502.93 | T17: =S17+L17*N17+K17 -> 27962.233 | U17: =MIN(T17,MAX(0,Q17-R17)) -> 758.27907 | V17: =MAX(0,Q17-R17-U17) -> 0 | W17: =IF(B17=策略字典!$A$3,MIN(L17+H17,CEILING(V17/(F17*(1-参数设置!$B$23)),G17)),0) -> 0 | X17: =W17*F17 -> 0 | Y17: =X17*参数设置!$B$23 -> 0 | Z17: =X17-Y17 -> 0 | AA17: =MAX(0,V17-Z17) -> 0 | AB17: =MAX(0,Z17-V17) -> 0 | AC17: =T17-U17+AB17 -> 27203.953 | AD17: =MAX(0,L17+H17-W17) -> 27500 | AE17: =AD17*F17 -> 275000 | AF17: =SUM($C$7:C17)-SUM($O$7:O17) -> 257400 | AG17: =AF17/D17 -> 299302.33 | AH17: =AE17+AC17 -> 302203.95 | AI17: =AH17-AG17-SUM($AA$7:AA17) -> 2901.6279 | AJ17: =R17+U17+MIN(Z17,V17)+AA17-Q17 -> 0
A18: =EDATE(DATE(YEAR(参数设置!$B$4),MONTH(参数设置!$B$4),1),ROW()-7) -> 46569 | B18: 策略一：消费贷款+买基金 | C18: 23400 | D18: 0.86 | E18: =IF(B18=策略字典!$A$1,C18/D18,0) -> 27209.302 | F18: 10 | G18: 500 | H18: =IF(E18=0,0,FLOOR((E18-J18)/F18,G18)) -> 2500 | I18: =H18*F18 -> 25000 | J18: 0 | K18: =MAX(0,E18-I18-J18) -> 2209.3023 | L18: =IF(ROW()=7,0,AD17) -> 27500 | M18: =0 -> 0 | N18: 0.05 | O18: =SUMIFS(实际贷款明细!$I$4:$I$435,实际贷款明细!$G$4:$G$435,">="&A18,实际贷款明细!$G$4:$G$435,"<"&EDATE(A18,1)) -> 0 | P18: =SUMIFS(实际贷款明细!$J$4:$J$435,实际贷款明细!$G$4:$G$435,">="&A18,实际贷款明细!$G$4:$G$435,"<"&EDATE(A18,1)) -> 699.27 | Q18: =(O18+P18)/D18 -> 813.10465 | R18: =IF(B18=策略字典!$A$2,MIN(C18,O18)/D18,0) -> 0 | S18: =IF(ROW()=7,0,AC17) -> 27203.953 | T18: =S18+L18*N18+K18 -> 30788.256 | U18: =MIN(T18,MAX(0,Q18-R18)) -> 813.10465 | V18: =MAX(0,Q18-R18-U18) -> 0 | W18: =IF(B18=策略字典!$A$3,MIN(L18+H18,CEILING(V18/(F18*(1-参数设置!$B$23)),G18)),0) -> 0 | X18: =W18*F18 -> 0 | Y18: =X18*参数设置!$B$23 -> 0 | Z18: =X18-Y18 -> 0 | AA18: =MAX(0,V18-Z18) -> 0 | AB18: =MAX(0,Z18-V18) -> 0 | AC18: =T18-U18+AB18 -> 29975.151 | AD18: =MAX(0,L18+H18-W18) -> 30000 | AE18: =AD18*F18 -> 300000 | AF18: =SUM($C$7:C18)-SUM($O$7:O18) -> 280800 | AG18: =AF18/D18 -> 326511.63 | AH18: =AE18+AC18 -> 329975.15 | AI18: =AH18-AG18-SUM($AA$7:AA18) -> 3463.5233 | AJ18: =R18+U18+MIN(Z18,V18)+AA18-Q18 -> 0
